Workbook

Sheet RF_AUC
A1: Source→Target | B1: OTOMO | C1: CORAL | D1: TCA+ | E1: DPP | F1: ADASYN | G1: SMOTE | H1: TOMO | I1: Source | J1: OTOMO | K1: CORAL | L1: TCA+ | M1: DPP | N1: ADASYN | O1: SMOTE | P1: TOMO
A2: NASA | I2: NASA
A3: CM1→MW1 | B3: 0.7554 +/- 0.0103 | C3: 0.7272 +/- 0.0249 | D3: 0.7075 +/- 0.0174 | E3: 0.7927 +/- 0.0160 | F3: 0.7867 +/- 0.0107 | G3: 0.7815 +/- 0.0132 | H3: 0.5159 +/- 0.0234 | I3: =A3 -> CM1→MW1 | J3: =IFERROR(__xludf.DUMMYFUNCTION("TEXT(VALUE(REGEXEXTRACT(B3,""^[+-]?[0-9]*\.?[0-9]+""))*100,""0.00"")&"" +/- ""&TEXT(VALUE(REGEXEXTRACT(B3,""[0-9]*\.?[0-9]+$""))*100,""0.00"")"),"75.54 +/- 1.03") -> 75.54 +/- 1.03 | K3: =IFERROR(__xludf.DUMMYFUNCTION("TEXT(VALUE(REGEXEXTRACT(C3,""^[+-]?[0-9]*\.?[0-9]+""))*100,""0.00"")&"" +/- ""&TEXT(VALUE(REGEXEXTRACT(C3,""[0-9]*\.?[0-9]+$""))*100,""0.00"")"),"72.72 +/- 2.49") -> 72.72 +/- 2.49 | L3: =IFERROR(__xludf.DUMMYFUNCTION("TEXT(VALUE(REGEXEXTRACT(D3,""^[+-]?[0-9]*\.?[0-9]+""))*100,""0.00"")&"" +/- ""&TEXT(VALUE(REGEXEXTRACT(D3,""[0-9]*\.?[0-9]+$""))*100,""0.00"")"),"70.75 +/- 1.74") -> 70.75 +/- 1.74 | M3: =IFERROR(__xludf.DUMMYFUNCTION("TEXT(VALUE(REGEXEXTRACT(E3,""^[+-]?[0-9]*\.?[0-9]+""))*100,""0.00"")&"" +/- ""&TEXT(VALUE(REGEXEXTRACT(E3,""[0-9]*\.?[0-9]+$""))*100,""0.00"")"),"79.27 +/- 1.60") -> 79.27 +/- 1.60 | N3: =IFERROR(__xludf.DUMMYFUNCTION("TEXT(VALUE(REGEXEXTRACT(F3,""^[+-]?[0-9]*\.?[0-9]+""))*100,""0.00"")&"" +/- ""&TEXT(VALUE(REGEXEXTRACT(F3,""[0-9]*\.?[0-9]+$""))*100,""0.00"")"),"78.67 +/- 1.07") -> 78.67 +/- 1.07 | O3: =IFERROR(__xludf.DUMMYFUNCTION("TEXT(VALUE(REGEXEXTRACT(G3,""^[+-]?[0-9]*\.?[0-9]+""))*100,""0.00"")&"" +/- ""&TEXT(VALUE(REGEXEXTRACT(G3,""[0-9]*\.?[0-9]+$""))*100,""0.00"")"),"78.15 +/- 1.32") -> 78.15 +/- 1.32 | P3: =IFERROR(__xludf.DUMMYFUNCTION("TEXT(VALUE(REGEXEXTRACT(H3,""^[+-]?[0-9]*\.?[0-9]+""))*100,""0.00"")&"" +/- ""&TEXT(VALUE(REGEXEXTRACT(H3,""[0-9]*\.?[0-9]+$""))*100,""0.00"")"),"51.59 +/- 2.34") -> 51.59 +/- 2.34
A4: CM1→PC1 | B4: 0.7377 +/- 0.0074 | C4: 0.8017 +/- 0.0078 | D4: 0.7924 +/- 0.0111 | E4: 0.7657 +/- 0.0129 | F4: 0.7628 +/- 0.0105 | G4: 0.7631 +/- 0.0101 | H4: 0.7733 +/- 0.0179 | I4: =A4 -> CM1→PC1 | J4: =IFERROR(__xludf.DUMMYFUNCTION("TEXT(VALUE(REGEXEXTRACT(B4,""^[+-]?[0-9]*\.?[0-9]+""))*100,""0.00"")&"" +/- ""&TEXT(VALUE(REGEXEXTRACT(B4,""[0-9]*\.?[0-9]+$""))*100,""0.00"")"),"73.77 +/- 0.74") -> 73.77 +/- 0.74 | K4: =IFERROR(__xludf.DUMMYFUNCTION("TEXT(VALUE(REGEXEXTRACT(C4,""^[+-]?[0-9]*\.?[0-9]+""))*100,""0.00"")&"" +/- ""&TEXT(VALUE(REGEXEXTRACT(C4,""[0-9]*\.?[0-9]+$""))*100,""0.00"")"),"80.17 +/- 0.78") -> 80.17 +/- 0.78 | L4: =IFERROR(__xludf.DUMMYFUNCTION("TEXT(VALUE(REGEXEXTRACT(D4,""^[+-]?[0-9]*\.?[0-9]+""))*100,""0.00"")&"" +/- ""&TEXT(VALUE(REGEXEXTRACT(D4,""[0-9]*\.?[0-9]+$""))*100,""0.00"")"),"79.24 +/- 1.11") -> 79.24 +/- 1.11 | M4: =IFERROR(__xludf.DUMMYFUNCTION("TEXT(VALUE(REGEXEXTRACT(E4,""^[+-]?[0-9]*\.?[0-9]+""))*100,""0.00"")&"" +/- ""&TEXT(VALUE(REGEXEXTRACT(E4,""[0-9]*\.?[0-9]+$""))*100,""0.00"")"),"76.57 +/- 1.29") -> 76.57 +/- 1.29 | N4: =IFERROR(__xludf.DUMMYFUNCTION("TEXT(VALUE(REGEXEXTRACT(F4,""^[+-]?[0-9]*\.?[0-9]+""))*100,""0.00"")&"" +/- ""&TEXT(VALUE(REGEXEXTRACT(F4,""[0-9]*\.?[0-9]+$""))*100,""0.00"")"),"76.28 +/- 1.05") -> 76.28 +/- 1.05 | O4: =IFERROR(__xludf.DUMMYFUNCTION("TEXT(VALUE(REGEXEXTRACT(G4,""^[+-]?[0-9]*\.?[0-9]+""))*100,""0.00"")&"" +/- ""&TEXT(VALUE(REGEXEXTRACT(G4,""[0-9]*\.?[0-9]+$""))*100,""0.00"")"),"76.31 +/- 1.01") -> 76.31 +/- 1.01 | P4: =IFERROR(__xludf.DUMMYFUNCTION("TEXT(VALUE(REGEXEXTRACT(H4,""^[+-]?[0-9]*\.?[0-9]+""))*100,""0.00"")&"" +/- ""&TEXT(VALUE(REGEXEXTRACT(H4,""[0-9]*\.?[0-9]+$""))*100,""0.00"")"),"77.33 +/- 1.79") -> 77.33 +/- 1.79
A5: CM1→PC3 | B5: 0.7754 +/- 0.0069 | C5: 0.7576 +/- 0.0070 | D5: 0.7463 +/- 0.0080 | E5: 0.7498 +/- 0.0099 | F5: 0.7342 +/- 0.0092 | G5: 0.7437 +/- 0.0136 | H5: 0.7307 +/- 0.0123 | I5: =A5 -> CM1→PC3 | J5: =IFERROR(__xludf.DUMMYFUNCTION("TEXT(VALUE(REGEXEXTRACT(B5,""^[+-]?[0-9]*\.?[0-9]+""))*100,""0.00"")&"" +/- ""&TEXT(VALUE(REGEXEXTRACT(B5,""[0-9]*\.?[0-9]+$""))*100,""0.00"")"),"77.54 +/- 0.69") -> 77.54 +/- 0.69 | K5: =IFERROR(__xludf.DUMMYFUNCTION("TEXT(VALUE(REGEXEXTRACT(C5,""^[+-]?[0-9]*\.?[0-9]+""))*100,""0.00"")&"" +/- ""&TEXT(VALUE(REGEXEXTRACT(C5,""[0-9]*\.?[0-9]+$""))*100,""0.00"")"),"75.76 +/- 0.70") -> 75.76 +/- 0.70 | L5: =IFERROR(__xludf.DUMMYFUNCTION("TEXT(VALUE(REGEXEXTRACT(D5,""^[+-]?[0-9]*\.?[0-9]+""))*100,""0.00"")&"" +/- ""&TEXT(VALUE(REGEXEXTRACT(D5,""[0-9]*\.?[0-9]+$""))*100,""0.00"")"),"74.63 +/- 0.80") -> 74.63 +/- 0.80 | M5: =IFERROR(__xludf.DUMMYFUNCTION("TEXT(VALUE(REGEXEXTRACT(E5,""^[+-]?[0-9]*\.?[0-9]+""))*100,""0.00"")&"" +/- ""&TEXT(VALUE(REGEXEXTRACT(E5,""[0-9]*\.?[0-9]+$""))*100,""0.00"")"),"74.98 +/- 0.99") -> 74.98 +/- 0.99 | N5: =IFERROR(__xludf.DUMMYFUNCTION("TEXT(VALUE(REGEXEXTRACT(F5,""^[+-]?[0-9]*\.?[0-9]+""))*100,""0.00"")&"" +/- ""&TEXT(VALUE(REGEXEXTRACT(F5,""[0-9]*\.?[0-9]+$""))*100,""0.00"")"),"73.42 +/- 0.92") -> 73.42 +/- 0.92 | O5: =IFERROR(__xludf.DUMMYFUNCTION("TEXT(VALUE(REGEXEXTRACT(G5,""^[+-]?[0-9]*\.?[0-9]+""))*100,""0.00"")&"" +/- ""&TEXT(VALUE(REGEXEXTRACT(G5,""[0-9]*\.?[0-9]+$""))*100,""0.00"")"),"74.37 +/- 1.36") -> 74.37 +/- 1.36 | P5: =IFERROR(__xludf.DUMMYFUNCTION("TEXT(VALUE(REGEXEXTRACT(H5,""^[+-]?[0-9]*\.?[0-9]+""))*100,""0.00"")&"" +/- ""&TEXT(VALUE(REGEXEXTRACT(H5,""[0-9]*\.?[0-9]+$""))*100,""0.00"")"),"73.07 +/- 1.23") -> 73.07 +/- 1.23
A6: CM1→PC4 | B6: 0.6771 +/- 0.0115 | C6: 0.6684 +/- 0.0126 | D6: 0.6027 +/- 0.0186 | E6: 0.6411 +/- 0.0187 | F6: 0.6788 +/- 0.0124 | G6: 0.6819 +/- 0.0134 | H6: 0.5866 +/- 0.0220 | I6: =A6 -> CM1→PC4 | J6: =IFERROR(__xludf.DUMMYFUNCTION("TEXT(VALUE(REGEXEXTRACT(B6,""^[+-]?[0-9]*\.?[0-9]+""))*100,""0.00"")&"" +/- ""&TEXT(VALUE(REGEXEXTRACT(B6,""[0-9]*\.?[0-9]+$""))*100,""0.00"")"),"67.71 +/- 1.15") -> 67.71 +/- 1.15 | K6: =IFERROR(__xludf.DUMMYFUNCTION("TEXT(VALUE(REGEXEXTRACT(C6,""^[+-]?[0-9]*\.?[0-9]+""))*100,""0.00"")&"" +/- ""&TEXT(VALUE(REGEXEXTRACT(C6,""[0-9]*\.?[0-9]+$""))*100,""0.00"")"),"66.84 +/- 1.26") -> 66.84 +/- 1.26 | L6: =IFERROR(__xludf.DUMMYFUNCTION("TEXT(VALUE(REGEXEXTRACT(D6,""^[+-]?[0-9]*\.?[0-9]+""))*100,""0.00"")&"" +/- ""&TEXT(VALUE(REGEXEXTRACT(D6,""[0-9]*\.?[0-9]+$""))*100,""0.00"")"),"60.27 +/- 1.86") -> 60.27 +/- 1.86 | M6: =IFERROR(__xludf.DUMMYFUNCTION("TEXT(VALUE(REGEXEXTRACT(E6,""^[+-]?[0-9]*\.?[0-9]+""))*100,""0.00"")&"" +/- ""&TEXT(VALUE(REGEXEXTRACT(E6,""[0-9]*\.?[0-9]+$""))*100,""0.00"")"),"64.11 +/- 1.87") -> 64.11 +/- 1.87 | N6: =IFERROR(__xludf.DUMMYFUNCTION("TEXT(VALUE(REGEXEXTRACT(F6,""^[+-]?[0-9]*\.?[0-9]+""))*100,""0.00"")&"" +/- ""&TEXT(VALUE(REGEXEXTRACT(F6,""[0-9]*\.?[0-9]+$""))*100,""0.00"")"),"67.88 +/- 1.24") -> 67.88 +/- 1.24 | O6: =IFERROR(__xludf.DUMMYFUNCTION("TEXT(VALUE(REGEXEXTRACT(G6,""^[+-]?[0-9]*\.?[0-9]+""))*100,""0.00"")&"" +/- ""&TEXT(VALUE(REGEXEXTRACT(G6,""[0-9]*\.?[0-9]+$""))*100,""0.00"")"),"68.19 +/- 1.34") -> 68.19 +/- 1.34 | P6: =IFERROR(__xludf.DUMMYFUNCTION("TEXT(VALUE(REGEXEXTRACT(H6,""^[+-]?[0-9]*\.?[0-9]+""))*100,""0.00"")&"" +/- ""&TEXT(VALUE(REGEXEXTRACT(H6,""[0-9]*\.?[0-9]+$""))*100,""0.00"")"),"58.66 +/- 2.20") -> 58.66 +/- 2.20
A7: MW1→CM1 | B7: 0.6980 +/- 0.0185 | C7: 0.6556 +/- 0.0152 | D7: 0.5461 +/- 0.0181 | E7: 0.6945 +/- 0.0172 | F7: 0.6809 +/- 0.0155 | G7: 0.6997 +/- 0.0196 | H7: 0.6879 +/- 0.0098 | I7: =A7 -> MW1→CM1 | J7: =IFERROR(__xludf.DUMMYFUNCTION("TEXT(VALUE(REGEXEXTRACT(B7,""^[+-]?[0-9]*\.?[0-9]+""))*100,""0.00"")&"" +/- ""&TEXT(VALUE(REGEXEXTRACT(B7,""[0-9]*\.?[0-9]+$""))*100,""0.00"")"),"69.80 +/- 1.85") -> 69.80 +/- 1.85 | K7: =IFERROR(__xludf.DUMMYFUNCTION("TEXT(VALUE(REGEXEXTRACT(C7,""^[+-]?[0-9]*\.?[0-9]+""))*100,""0.00"")&"" +/- ""&TEXT(VALUE(REGEXEXTRACT(C7,""[0-9]*\.?[0-9]+$""))*100,""0.00"")"),"65.56 +/- 1.52") -> 65.56 +/- 1.52 | L7: =IFERROR(__xludf.DUMMYFUNCTION("TEXT(VALUE(REGEXEXTRACT(D7,""^[+-]?[0-9]*\.?[0-9]+""))*100,""0.00"")&"" +/- ""&TEXT(VALUE(REGEXEXTRACT(D7,""[0-9]*\.?[0-9]+$""))*100,""0.00"")"),"54.61 +/- 1.81") -> 54.61 +/- 1.81 | M7: =IFERROR(__xludf.DUMMYFUNCTION("TEXT(VALUE(REGEXEXTRACT(E7,""^[+-]?[0-9]*\.?[0-9]+""))*100,""0.00"")&"" +/- ""&TEXT(VALUE(REGEXEXTRACT(E7,""[0-9]*\.?[0-9]+$""))*100,""0.00"")"),"69.45 +/- 1.72") -> 69.45 +/- 1.72 | N7: =IFERROR(__xludf.DUMMYFUNCTION("TEXT(VALUE(REGEXEXTRACT(F7,""^[+-]?[0-9]*\.?[0-9]+""))*100,""0.00"")&"" +/- ""&TEXT(VALUE(REGEXEXTRACT(F7,""[0-9]*\.?[0-9]+$""))*100,""0.00"")"),"68.09 +/- 1.55") -> 68.09 +/- 1.55 | O7: =IFERROR(__xludf.DUMMYFUNCTION("TEXT(VALUE(REGEXEXTRACT(G7,""^[+-]?[0-9]*\.?[0-9]+""))*100,""0.00"")&"" +/- ""&TEXT(VALUE(REGEXEXTRACT(G7,""[0-9]*\.?[0-9]+$""))*100,""0.00"")"),"69.97 +/- 1.96") -> 69.97 +/- 1.96 | P7: =IFERROR(__xludf.DUMMYFUNCTION("TEXT(VALUE(REGEXEXTRACT(H7,""^[+-]?[0-9]*\.?[0-9]+""))*100,""0.00"")&"" +/- ""&TEXT(VALUE(REGEXEXTRACT(H7,""[0-9]*\.?[0-9]+$""))*100,""0.00"")"),"68.79 +/- 0.98") -> 68.79 +/- 0.98
A8: MW1→PC1 | B8: 0.7550 +/- 0.0207 | C8: 0.7642 +/- 0.0220 | D8: 0.7033 +/- 0.0211 | E8: 0.7510 +/- 0.0253 | F8: 0.6985 +/- 0.0312 | G8: 0.7223 +/- 0.0305 | H8: 0.7450 +/- 0.0144 | I8: =A8 -> MW1→PC1 | J8: =IFERROR(__xludf.DUMMYFUNCTION("TEXT(VALUE(REGEXEXTRACT(B8,""^[+-]?[0-9]*\.?[0-9]+""))*100,""0.00"")&"" +/- ""&TEXT(VALUE(REGEXEXTRACT(B8,""[0-9]*\.?[0-9]+$""))*100,""0.00"")"),"75.50 +/- 2.07") -> 75.50 +/- 2.07 | K8: =IFERROR(__xludf.DUMMYFUNCTION("TEXT(VALUE(REGEXEXTRACT(C8,""^[+-]?[0-9]*\.?[0-9]+""))*100,""0.00"")&"" +/- ""&TEXT(VALUE(REGEXEXTRACT(C8,""[0-9]*\.?[0-9]+$""))*100,""0.00"")"),"76.42 +/- 2.20") -> 76.42 +/- 2.20 | L8: =IFERROR(__xludf.DUMMYFUNCTION("TEXT(VALUE(REGEXEXTRACT(D8,""^[+-]?[0-9]*\.?[0-9]+""))*100,""0.00"")&"" +/- ""&TEXT(VALUE(REGEXEXTRACT(D8,""[0-9]*\.?[0-9]+$""))*100,""0.00"")"),"70.33 +/- 2.11") -> 70.33 +/- 2.11 | M8: =IFERROR(__xludf.DUMMYFUNCTION("TEXT(VALUE(REGEXEXTRACT(E8,""^[+-]?[0-9]*\.?[0-9]+""))*100,""0.00"")&"" +/- ""&TEXT(VALUE(REGEXEXTRACT(E8,""[0-9]*\.?[0-9]+$""))*100,""0.00"")"),"75.10 +/- 2.53") -> 75.10 +/- 2.53 | N8: =IFERROR(__xludf.DUMMYFUNCTION("TEXT(VALUE(REGEXEXTRACT(F8,""^[+-]?[0-9]*\.?[0-9]+""))*100,""0.00"")&"" +/- ""&TEXT(VALUE(REGEXEXTRACT(F8,""[0-9]*\.?[0-9]+$""))*100,""0.00"")"),"69.85 +/- 3.12") -> 69.85 +/- 3.12 | O8: =IFERROR(__xludf.DUMMYFUNCTION("TEXT(VALUE(REGEXEXTRACT(G8,""^[+-]?[0-9]*\.?[0-9]+""))*100,""0.00"")&"" +/- ""&TEXT(VALUE(REGEXEXTRACT(G8,""[0-9]*\.?[0-9]+$""))*100,""0.00"")"),"72.23 +/- 3.05") -> 72.23 +/- 3.05 | P8: =IFERROR(__xludf.DUMMYFUNCTION("TEXT(VALUE(REGEXEXTRACT(H8,""^[+-]?[0-9]*\.?[0-9]+""))*100,""0.00"")&"" +/- ""&TEXT(VALUE(REGEXEXTRACT(H8,""[0-9]*\.?[0-9]+$""))*100,""0.00"")"),"74.50 +/- 1.44") -> 74.50 +/- 1.44
A9: MW1→PC3 | B9: 0.7490 +/- 0.0245 | C9: 0.6535 +/- 0.0217 | D9: 0.6366 +/- 0.0266 | E9: 0.5836 +/- 0.0341 | F9: 0.5275 +/- 0.0186 | G9: 0.5280 +/- 0.0271 | H9: 0.6756 +/- 0.0242 | I9: =A9 -> MW1→PC3 | J9: =IFERROR(__xludf.DUMMYFUNCTION("TEXT(VALUE(REGEXEXTRACT(B9,""^[+-]?[0-9]*\.?[0-9]+""))*100,""0.00"")&"" +/- ""&TEXT(VALUE(REGEXEXTRACT(B9,""[0-9]*\.?[0-9]+$""))*100,""0.00"")"),"74.90 +/- 2.45") -> 74.90 +/- 2.45 | K9: =IFERROR(__xludf.DUMMYFUNCTION("TEXT(VALUE(REGEXEXTRACT(C9,""^[+-]?[0-9]*\.?[0-9]+""))*100,""0.00"")&"" +/- ""&TEXT(VALUE(REGEXEXTRACT(C9,""[0-9]*\.?[0-9]+$""))*100,""0.00"")"),"65.35 +/- 2.17") -> 65.35 +/- 2.17 | L9: =IFERROR(__xludf.DUMMYFUNCTION("TEXT(VALUE(REGEXEXTRACT(D9,""^[+-]?[0-9]*\.?[0-9]+""))*100,""0.00"")&"" +/- ""&TEXT(VALUE(REGEXEXTRACT(D9,""[0-9]*\.?[0-9]+$""))*100,""0.00"")"),"63.66 +/- 2.66") -> 63.66 +/- 2.66 | M9: =IFERROR(__xludf.DUMMYFUNCTION("TEXT(VALUE(REGEXEXTRACT(E9,""^[+-]?[0-9]*\.?[0-9]+""))*100,""0.00"")&"" +/- ""&TEXT(VALUE(REGEXEXTRACT(E9,""[0-9]*\.?[0-9]+$""))*100,""0.00"")"),"58.36 +/- 3.41") -> 58.36 +/- 3.41 | N9: =IFERROR(__xludf.DUMMYFUNCTION("TEXT(VALUE(REGEXEXTRACT(F9,""^[+-]?[0-9]*\.?[0-9]+""))*100,""0.00"")&"" +/- ""&TEXT(VALUE(REGEXEXTRACT(F9,""[0-9]*\.?[0-9]+$""))*100,""0.00"")"),"52.75 +/- 1.86") -> 52.75 +/- 1.86 | O9: =IFERROR(__xludf.DUMMYFUNCTION("TEXT(VALUE(REGEXEXTRACT(G9,""^[+-]?[0-9]*\.?[0-9]+""))*100,""0.00"")&"" +/- ""&TEXT(VALUE(REGEXEXTRACT(G9,""[0-9]*\.?[0-9]+$""))*100,""0.00"")"),"52.80 +/- 2.71") -> 52.80 +/- 2.71 | P9: =IFERROR(__xludf.DUMMYFUNCTION("TEXT(VALUE(REGEXEXTRACT(H9,""^[+-]?[0-9]*\.?[0-9]+""))*100,""0.00"")&"" +/- ""&TEXT(VALUE(REGEXEXTRACT(H9,""[0-9]*\.?[0-9]+$""))*100,""0.00"")"),"67.56 +/- 2.42") -> 67.56 +/- 2.42
A10: MW1→PC4 | B10: 0.6790 +/- 0.0180 | C10: 0.5528 +/- 0.0445 | D10: 0.6341 +/- 0.0128 | E10: 0.6183 +/- 0.0391 | F10: 0.5782 +/- 0.0280 | G10: 0.5782 +/- 0.0403 | H10: 0.5629 +/- 0.0256 | I10: =A10 -> MW1→PC4 | J10: =IFERROR(__xludf.DUMMYFUNCTION("TEXT(VALUE(REGEXEXTRACT(B10,""^[+-]?[0-9]*\.?[0-9]+""))*100,""0.00"")&"" +/- ""&TEXT(VALUE(REGEXEXTRACT(B10,""[0-9]*\.?[0-9]+$""))*100,""0.00"")"),"67.90 +/- 1.80") -> 67.90 +/- 1.80 | K10: =IFERROR(__xludf.DUMMYFUNCTION("TEXT(VALUE(REGEXEXTRACT(C10,""^[+-]?[0-9]*\.?[0-9]+""))*100,""0.00"")&"" +/- ""&TEXT(VALUE(REGEXEXTRACT(C10,""[0-9]*\.?[0-9]+$""))*100,""0.00"")"),"55.28 +/- 4.45") -> 55.28 +/- 4.45 | L10: =IFERROR(__xludf.DUMMYFUNCTION("TEXT(VALUE(REGEXEXTRACT(D10,""^[+-]?[0-9]*\.?[0-9]+""))*100,""0.00"")&"" +/- ""&TEXT(VALUE(REGEXEXTRACT(D10,""[0-9]*\.?[0-9]+$""))*100,""0.00"")"),"63.41 +/- 1.28") -> 63.41 +/- 1.28 | M10: =IFERROR(__xludf.DUMMYFUNCTION("TEXT(VALUE(REGEXEXTRACT(E10,""^[+-]?[0-9]*\.?[0-9]+""))*100,""0.00"")&"" +/- ""&TEXT(VALUE(REGEXEXTRACT(E10,""[0-9]*\.?[0-9]+$""))*100,""0.00"")"),"61.83 +/- 3.91") -> 61.83 +/- 3.91 | N10: =IFERROR(__xludf.DUMMYFUNCTION("TEXT(VALUE(REGEXEXTRACT(F10,""^[+-]?[0-9]*\.?[0-9]+""))*100,""0.00"")&"" +/- ""&TEXT(VALUE(REGEXEXTRACT(F10,""[0-9]*\.?[0-9]+$""))*100,""0.00"")"),"57.82 +/- 2.80") -> 57.82 +/- 2.80 | O10: =IFERROR(__xludf.DUMMYFUNCTION("TEXT(VALUE(REGEXEXTRACT(G10,""^[+-]?[0-9]*\.?[0-9]+""))*100,""0.00"")&"" +/- ""&TEXT(VALUE(REGEXEXTRACT(G10,""[0-9]*\.?[0-9]+$""))*100,""0.00"")"),"57.82 +/- 4.03") -> 57.82 +/- 4.03 | P10: =IFERROR(__xludf.DUMMYFUNCTION("TEXT(VALUE(REGEXEXTRACT(H10,""^[+-]?[0-9]*\.?[0-9]+""))*100,""0.00"")&"" +/- ""&TEXT(VALUE(REGEXEXTRACT(H10,""[0-9]*\.?[0-9]+$""))*100,""0.00"")"),"56.29 +/- 2.56") -> 56.29 +/- 2.56
A11: PC1→CM1 | B11: 0.6814 +/- 0.0128 | C11: 0.6530 +/- 0.0127 | D11: 0.6670 +/- 0.0160 | E11: 0.6911 +/- 0.0146 | F11: 0.6942 +/- 0.0113 | G11: 0.6997 +/- 0.0103 | H11: 0.4643 +/- 0.0157 | I11: =A11 -> PC1→CM1 | J11: =IFERROR(__xludf.DUMMYFUNCTION("TEXT(VALUE(REGEXEXTRACT(B11,""^[+-]?[0-9]*\.?[0-9]+""))*100,""0.00"")&"" +/- ""&TEXT(VALUE(REGEXEXTRACT(B11,""[0-9]*\.?[0-9]+$""))*100,""0.00"")"),"68.14 +/- 1.28") -> 68.14 +/- 1.28 | K11: =IFERROR(__xludf.DUMMYFUNCTION("TEXT(VALUE(REGEXEXTRACT(C11,""^[+-]?[0-9]*\.?[0-9]+""))*100,""0.00"")&"" +/- ""&TEXT(VALUE(REGEXEXTRACT(C11,""[0-9]*\.?[0-9]+$""))*100,""0.00"")"),"65.30 +/- 1.27") -> 65.30 +/- 1.27 | L11: =IFERROR(__xludf.DUMMYFUNCTION("TEXT(VALUE(REGEXEXTRACT(D11,""^[+-]?[0-9]*\.?[0-9]+""))*100,""0.00"")&"" +/- ""&TEXT(VALUE(REGEXEXTRACT(D11,""[0-9]*\.?[0-9]+$""))*100,""0.00"")"),"66.70 +/- 1.60") -> 66.70 +/- 1.60 | M11: =IFERROR(__xludf.DUMMYFUNCTION("TEXT(VALUE(REGEXEXTRACT(E11,""^[+-]?[0-9]*\.?[0-9]+""))*100,""0.00"")&"" +/- ""&TEXT(VALUE(REGEXEXTRACT(E11,""[0-9]*\.?[0-9]+$""))*100,""0.00"")"),"69.11 +/- 1.46") -> 69.11 +/- 1.46 | N11: =IFERROR(__xludf.DUMMYFUNCTION("TEXT(VALUE(REGEXEXTRACT(F11,""^[+-]?[0-9]*\.?[0-9]+""))*100,""0.00"")&"" +/- ""&TEXT(VALUE(REGEXEXTRACT(F11,""[0-9]*\.?[0-9]+$""))*100,""0.00"")"),"69.42 +/- 1.13") -> 69.42 +/- 1.13 | O11: =IFERROR(__xludf.DUMMYFUNCTION("TEXT(VALUE(REGEXEXTRACT(G11,""^[+-]?[0-9]*\.?[0-9]+""))*100,""0.00"")&"" +/- ""&TEXT(VALUE(REGEXEXTRACT(G11,""[0-9]*\.?[0-9]+$""))*100,""0.00"")"),"69.97 +/- 1.03") -> 69.97 +/- 1.03 | P11: =IFERROR(__xludf.DUMMYFUNCTION("TEXT(VALUE(REGEXEXTRACT(H11,""^[+-]?[0-9]*\.?[0-9]+""))*100,""0.00"")&"" +/- ""&TEXT(VALUE(REGEXEXTRACT(H11,""[0-9]*\.?[0-9]+$""))*100,""0.00"")"),"46.43 +/- 1.57") -> 46.43 +/- 1.57
A12: PC1→MW1 | B12: 0.7748 +/- 0.0098 | C12: 0.6795 +/- 0.0201 | D12: 0.6402 +/- 0.0278 | E12: 0.8043 +/- 0.0144 | F12: 0.7965 +/- 0.0107 | G12: 0.7954 +/- 0.0079 | H12: 0.5898 +/- 0.0212 | I12: =A12 -> PC1→MW1 | J12: =IFERROR(__xludf.DUMMYFUNCTION("TEXT(VALUE(REGEXEXTRACT(B12,""^[+-]?[0-9]*\.?[0-9]+""))*100,""0.00"")&"" +/- ""&TEXT(VALUE(REGEXEXTRACT(B12,""[0-9]*\.?[0-9]+$""))*100,""0.00"")"),"77.48 +/- 0.98") -> 77.48 +/- 0.98 | K12: =IFERROR(__xludf.DUMMYFUNCTION("TEXT(VALUE(REGEXEXTRACT(C12,""^[+-]?[0-9]*\.?[0-9]+""))*100,""0.00"")&"" +/- ""&TEXT(VALUE(REGEXEXTRACT(C12,""[0-9]*\.?[0-9]+$""))*100,""0.00"")"),"67.95 +/- 2.01") -> 67.95 +/- 2.01 | L12: =IFERROR(__xludf.DUMMYFUNCTION("TEXT(VALUE(REGEXEXTRACT(D12,""^[+-]?[0-9]*\.?[0-9]+""))*100,""0.00"")&"" +/- ""&TEXT(VALUE(REGEXEXTRACT(D12,""[0-9]*\.?[0-9]+$""))*100,""0.00"")"),"64.02 +/- 2.78") -> 64.02 +/- 2.78 | M12: =IFERROR(__xludf.DUMMYFUNCTION("TEXT(VALUE(REGEXEXTRACT(E12,""^[+-]?[0-9]*\.?[0-9]+""))*100,""0.00"")&"" +/- ""&TEXT(VALUE(REGEXEXTRACT(E12,""[0-9]*\.?[0-9]+$""))*100,""0.00"")"),"80.43 +/- 1.44") -> 80.43 +/- 1.44 | N12: =IFERROR(__xludf.DUMMYFUNCTION("TEXT(VALUE(REGEXEXTRACT(F12,""^[+-]?[0-9]*\.?[0-9]+""))*100,""0.00"")&"" +/- ""&TEXT(VALUE(REGEXEXTRACT(F12,""[0-9]*\.?[0-9]+$""))*100,""0.00"")"),"79.65 +/- 1.07") -> 79.65 +/- 1.07 | O12: =IFERROR(__xludf.DUMMYFUNCTION("TEXT(VALUE(REGEXEXTRACT(G12,""^[+-]?[0-9]*\.?[0-9]+""))*100,""0.00"")&"" +/- ""&TEXT(VALUE(REGEXEXTRACT(G12,""[0-9]*\.?[0-9]+$""))*100,""0.00"")"),"79.54 +/- 0.79") -> 79.54 +/- 0.79 | P12: =IFERROR(__xludf.DUMMYFUNCTION("TEXT(VALUE(REGEXEXTRACT(H12,""^[+-]?[0-9]*\.?[0-9]+""))*100,""0.00"")&"" +/- ""&TEXT(VALUE(REGEXEXTRACT(H12,""[0-9]*\.?[0-9]+$""))*100,""0.00"")"),"58.98 +/- 2.12") -> 58.98 +/- 2.12
A13: PC1→PC3 | B13: 0.8083 +/- 0.0053 | C13: 0.7310 +/- 0.0160 | D13: 0.7504 +/- 0.0090 | E13: 0.8069 +/- 0.0067 | F13: 0.8130 +/- 0.0045 | G13: 0.8130 +/- 0.0044 | H13: 0.6929 +/- 0.0294 | I13: =A13 -> PC1→PC3 | J13: =IFERROR(__xludf.DUMMYFUNCTION("TEXT(VALUE(REGEXEXTRACT(B13,""^[+-]?[0-9]*\.?[0-9]+""))*100,""0.00"")&"" +/- ""&TEXT(VALUE(REGEXEXTRACT(B13,""[0-9]*\.?[0-9]+$""))*100,""0.00"")"),"80.83 +/- 0.53") -> 80.83 +/- 0.53 | K13: =IFERROR(__xludf.DUMMYFUNCTION("TEXT(VALUE(REGEXEXTRACT(C13,""^[+-]?[0-9]*\.?[0-9]+""))*100,""0.00"")&"" +/- ""&TEXT(VALUE(REGEXEXTRACT(C13,""[0-9]*\.?[0-9]+$""))*100,""0.00"")"),"73.10 +/- 1.60") -> 73.10 +/- 1.60 | L13: =IFERROR(__xludf.DUMMYFUNCTION("TEXT(VALUE(REGEXEXTRACT(D13,""^[+-]?[0-9]*\.?[0-9]+""))*100,""0.00"")&"" +/- ""&TEXT(VALUE(REGEXEXTRACT(D13,""[0-9]*\.?[0-9]+$""))*100,""0.00"")"),"75.04 +/- 0.90") -> 75.04 +/- 0.90 | M13: =IFERROR(__xludf.DUMMYFUNCTION("TEXT(VALUE(REGEXEXTRACT(E13,""^[+-]?[0-9]*\.?[0-9]+""))*100,""0.00"")&"" +/- ""&TEXT(VALUE(REGEXEXTRACT(E13,""[0-9]*\.?[0-9]+$""))*100,""0.00"")"),"80.69 +/- 0.67") -> 80.69 +/- 0.67 | N13: =IFERROR(__xludf.DUMMYFUNCTION("TEXT(VALUE(REGEXEXTRACT(F13,""^[+-]?[0-9]*\.?[0-9]+""))*100,""0.00"")&"" +/- ""&TEXT(VALUE(REGEXEXTRACT(F13,""[0-9]*\.?[0-9]+$""))*100,""0.00"")"),"81.30 +/- 0.45") -> 81.30 +/- 0.45 | O13: =IFERROR(__xludf.DUMMYFUNCTION("TEXT(VALUE(REGEXEXTRACT(G13,""^[+-]?[0-9]*\.?[0-9]+""))*100,""0.00"")&"" +/- ""&TEXT(VALUE(REGEXEXTRACT(G13,""[0-9]*\.?[0-9]+$""))*100,""0.00"")"),"81.30 +/- 0.44") -> 81.30 +/- 0.44 | P13: =IFERROR(__xludf.DUMMYFUNCTION("TEXT(VALUE(REGEXEXTRACT(H13,""^[+-]?[0-9]*\.?[0-9]+""))*100,""0.00"")&"" +/- ""&TEXT(VALUE(REGEXEXTRACT(H13,""[0-9]*\.?[0-9]+$""))*100,""0.00"")"),"69.29 +/- 2.94") -> 69.29 +/- 2.94
A14: PC1→PC4 | B14: 0.7304 +/- 0.0098 | C14: 0.7199 +/- 0.0179 | D14: 0.6489 +/- 0.0134 | E14: 0.7453 +/- 0.0123 | F14: 0.7688 +/- 0.0089 | G14: 0.7655 +/- 0.0063 | H14: 0.5144 +/- 0.0230 | I14: =A14 -> PC1→PC4 | J14: =IFERROR(__xludf.DUMMYFUNCTION("TEXT(VALUE(REGEXEXTRACT(B14,""^[+-]?[0-9]*\.?[0-9]+""))*100,""0.00"")&"" +/- ""&TEXT(VALUE(REGEXEXTRACT(B14,""[0-9]*\.?[0-9]+$""))*100,""0.00"")"),"73.04 +/- 0.98") -> 73.04 +/- 0.98 | K14: =IFERROR(__xludf.DUMMYFUNCTION("TEXT(VALUE(REGEXEXTRACT(C14,""^[+-]?[0-9]*\.?[0-9]+""))*100,""0.00"")&"" +/- ""&TEXT(VALUE(REGEXEXTRACT(C14,""[0-9]*\.?[0-9]+$""))*100,""0.00"")"),"71.99 +/- 1.79") -> 71.99 +/- 1.79 | L14: =IFERROR(__xludf.DUMMYFUNCTION("TEXT(VALUE(REGEXEXTRACT(D14,""^[+-]?[0-9]*\.?[0-9]+""))*100,""0.00"")&"" +/- ""&TEXT(VALUE(REGEXEXTRACT(D14,""[0-9]*\.?[0-9]+$""))*100,""0.00"")"),"64.89 +/- 1.34") -> 64.89 +/- 1.34 | M14: =IFERROR(__xludf.DUMMYFUNCTION("TEXT(VALUE(REGEXEXTRACT(E14,""^[+-]?[0-9]*\.?[0-9]+""))*100,""0.00"")&"" +/- ""&TEXT(VALUE(REGEXEXTRACT(E14,""[0-9]*\.?[0-9]+$""))*100,""0.00"")"),"74.53 +/- 1.23") -> 74.53 +/- 1.23 | N14: =IFERROR(__xludf.DUMMYFUNCTION("TEXT(VALUE(REGEXEXTRACT(F14,""^[+-]?[0-9]*\.?[0-9]+""))*100,""0.00"")&"" +/- ""&TEXT(VALUE(REGEXEXTRACT(F14,""[0-9]*\.?[0-9]+$""))*100,""0.00"")"),"76.88 +/- 0.89") -> 76.88 +/- 0.89 | O14: =IFERROR(__xludf.DUMMYFUNCTION("TEXT(VALUE(REGEXEXTRACT(G14,""^[+-]?[0-9]*\.?[0-9]+""))*100,""0.00"")&"" +/- ""&TEXT(VALUE(REGEXEXTRACT(G14,""[0-9]*\.?[0-9]+$""))*100,""0.00"")"),"76.55 +/- 0.63") -> 76.55 +/- 0.63 | P14: =IFERROR(__xludf.DUMMYFUNCTION("TEXT(VALUE(REGEXEXTRACT(H14,""^[+-]?[0-9]*\.?[0-9]+""))*100,""0.00"")&"" +/- ""&TEXT(VALUE(REGEXEXTRACT(H14,""[0-9]*\.?[0-9]+$""))*100,""0.00"")"),"51.44 +/- 2.30") -> 51.44 +/- 2.30
A15: PC3→CM1 | B15: 0.6499 +/- 0.0145 | C15: 0.6290 +/- 0.0134 | D15: 0.6636 +/- 0.0139 | E15: 0.6508 +/- 0.0088 | F15: 0.6776 +/- 0.0096 | G15: 0.6745 +/- 0.0103 | H15: 0.4884 +/- 0.0213 | I15: =A15 -> PC3→CM1 | J15: =IFERROR(__xludf.DUMMYFUNCTION("TEXT(VALUE(REGEXEXTRACT(B15,""^[+-]?[0-9]*\.?[0-9]+""))*100,""0.00"")&"" +/- ""&TEXT(VALUE(REGEXEXTRACT(B15,""[0-9]*\.?[0-9]+$""))*100,""0.00"")"),"64.99 +/- 1.45") -> 64.99 +/- 1.45 | K15: =IFERROR(__xludf.DUMMYFUNCTION("TEXT(VALUE(REGEXEXTRACT(C15,""^[+-]?[0-9]*\.?[0-9]+""))*100,""0.00"")&"" +/- ""&TEXT(VALUE(REGEXEXTRACT(C15,""[0-9]*\.?[0-9]+$""))*100,""0.00"")"),"62.90 +/- 1.34") -> 62.90 +/- 1.34 | L15: =IFERROR(__xludf.DUMMYFUNCTION("TEXT(VALUE(REGEXEXTRACT(D15,""^[+-]?[0-9]*\.?[0-9]+""))*100,""0.00"")&"" +/- ""&TEXT(VALUE(REGEXEXTRACT(D15,""[0-9]*\.?[0-9]+$""))*100,""0.00"")"),"66.36 +/- 1.39") -> 66.36 +/- 1.39 | M15: =IFERROR(__xludf.DUMMYFUNCTION("TEXT(VALUE(REGEXEXTRACT(E15,""^[+-]?[0-9]*\.?[0-9]+""))*100,""0.00"")&"" +/- ""&TEXT(VALUE(REGEXEXTRACT(E15,""[0-9]*\.?[0-9]+$""))*100,""0.00"")"),"65.08 +/- 0.88") -> 65.08 +/- 0.88 | N15: =IFERROR(__xludf.DUMMYFUNCTION("TEXT(VALUE(REGEXEXTRACT(F15,""^[+-]?[0-9]*\.?[0-9]+""))*100,""0.00"")&"" +/- ""&TEXT(VALUE(REGEXEXTRACT(F15,""[0-9]*\.?[0-9]+$""))*100,""0.00"")"),"67.76 +/- 0.96") -> 67.76 +/- 0.96 | O15: =IFERROR(__xludf.DUMMYFUNCTION("TEXT(VALUE(REGEXEXTRACT(G15,""^[+-]?[0-9]*\.?[0-9]+""))*100,""0.00"")&"" +/- ""&TEXT(VALUE(REGEXEXTRACT(G15,""[0-9]*\.?[0-9]+$""))*100,""0.00"")"),"67.45 +/- 1.03") -> 67.45 +/- 1.03 | P15: =IFERROR(__xludf.DUMMYFUNCTION("TEXT(VALUE(REGEXEXTRACT(H15,""^[+-]?[0-9]*\.?[0-9]+""))*100,""0.00"")&"" +/- ""&TEXT(VALUE(REGEXEXTRACT(H15,""[0-9]*\.?[0-9]+$""))*100,""0.00"")"),"48.84 +/- 2.13") -> 48.84 +/- 2.13
A16: PC3→MW1 | B16: 0.7031 +/- 0.0096 | C16: 0.6075 +/- 0.0260 | D16: 0.7329 +/- 0.0210 | E16: 0.7162 +/- 0.0126 | F16: 0.7188 +/- 0.0098 | G16: 0.7217 +/- 0.0116 | H16: 0.4153 +/- 0.0202 | I16: =A16 -> PC3→MW1 | J16: =IFERROR(__xludf.DUMMYFUNCTION("TEXT(VALUE(REGEXEXTRACT(B16,""^[+-]?[0-9]*\.?[0-9]+""))*100,""0.00"")&"" +/- ""&TEXT(VALUE(REGEXEXTRACT(B16,""[0-9]*\.?[0-9]+$""))*100,""0.00"")"),"70.31 +/- 0.96") -> 70.31 +/- 0.96 | K16: =IFERROR(__xludf.DUMMYFUNCTION("TEXT(VALUE(REGEXEXTRACT(C16,""^[+-]?[0-9]*\.?[0-9]+""))*100,""0.00"")&"" +/- ""&TEXT(VALUE(REGEXEXTRACT(C16,""[0-9]*\.?[0-9]+$""))*100,""0.00"")"),"60.75 +/- 2.60") -> 60.75 +/- 2.60 | L16: =IFERROR(__xludf.DUMMYFUNCTION("TEXT(VALUE(REGEXEXTRACT(D16,""^[+-]?[0-9]*\.?[0-9]+""))*100,""0.00"")&"" +/- ""&TEXT(VALUE(REGEXEXTRACT(D16,""[0-9]*\.?[0-9]+$""))*100,""0.00"")"),"73.29 +/- 2.10") -> 73.29 +/- 2.10 | M16: =IFERROR(__xludf.DUMMYFUNCTION("TEXT(VALUE(REGEXEXTRACT(E16,""^[+-]?[0-9]*\.?[0-9]+""))*100,""0.00"")&"" +/- ""&TEXT(VALUE(REGEXEXTRACT(E16,""[0-9]*\.?[0-9]+$""))*100,""0.00"")"),"71.62 +/- 1.26") -> 71.62 +/- 1.26 | N16: =IFERROR(__xludf.DUMMYFUNCTION("TEXT(VALUE(REGEXEXTRACT(F16,""^[+-]?[0-9]*\.?[0-9]+""))*100,""0.00"")&"" +/- ""&TEXT(VALUE(REGEXEXTRACT(F16,""[0-9]*\.?[0-9]+$""))*100,""0.00"")"),"71.88 +/- 0.98") -> 71.88 +/- 0.98 | O16: =IFERROR(__xludf.DUMMYFUNCTION("TEXT(VALUE(REGEXEXTRACT(G16,""^[+-]?[0-9]*\.?[0-9]+""))*100,""0.00"")&"" +/- ""&TEXT(VALUE(REGEXEXTRACT(G16,""[0-9]*\.?[0-9]+$""))*100,""0.00"")"),"72.17 +/- 1.16") -> 72.17 +/- 1.16 | P16: =IFERROR(__xludf.DUMMYFUNCTION("TEXT(VALUE(REGEXEXTRACT(H16,""^[+-]?[0-9]*\.?[0-9]+""))*100,""0.00"")&"" +/- ""&TEXT(VALUE(REGEXEXTRACT(H16,""[0-9]*\.?[0-9]+$""))*100,""0.00"")"),"41.53 +/- 2.02") -> 41.53 +/- 2.02
A17: PC3→PC1 | B17: 0.7729 +/- 0.0111 | C17: 0.8051 +/- 0.0065 | D17: 0.7806 +/- 0.0096 | E17: 0.8026 +/- 0.0097 | F17: 0.7931 +/- 0.0048 | G17: 0.7959 +/- 0.0072 | H17: 0.7727 +/- 0.0130 | I17: =A17 -> PC3→PC1 | J17: =IFERROR(__xludf.DUMMYFUNCTION("TEXT(VALUE(REGEXEXTRACT(B17,""^[+-]?[0-9]*\.?[0-9]+""))*100,""0.00"")&"" +/- ""&TEXT(VALUE(REGEXEXTRACT(B17,""[0-9]*\.?[0-9]+$""))*100,""0.00"")"),"77.29 +/- 1.11") -> 77.29 +/- 1.11 | K17: =IFERROR(__xludf.DUMMYFUNCTION("TEXT(VALUE(REGEXEXTRACT(C17,""^[+-]?[0-9]*\.?[0-9]+""))*100,""0.00"")&"" +/- ""&TEXT(VALUE(REGEXEXTRACT(C17,""[0-9]*\.?[0-9]+$""))*100,""0.00"")"),"80.51 +/- 0.65") -> 80.51 +/- 0.65 | L17: =IFERROR(__xludf.DUMMYFUNCTION("TEXT(VALUE(REGEXEXTRACT(D17,""^[+-]?[0-9]*\.?[0-9]+""))*100,""0.00"")&"" +/- ""&TEXT(VALUE(REGEXEXTRACT(D17,""[0-9]*\.?[0-9]+$""))*100,""0.00"")"),"78.06 +/- 0.96") -> 78.06 +/- 0.96 | M17: =IFERROR(__xludf.DUMMYFUNCTION("TEXT(VALUE(REGEXEXTRACT(E17,""^[+-]?[0-9]*\.?[0-9]+""))*100,""0.00"")&"" +/- ""&TEXT(VALUE(REGEXEXTRACT(E17,""[0-9]*\.?[0-9]+$""))*100,""0.00"")"),"80.26 +/- 0.97") -> 80.26 +/- 0.97 | N17: =IFERROR(__xludf.DUMMYFUNCTION("TEXT(VALUE(REGEXEXTRACT(F17,""^[+-]?[0-9]*\.?[0-9]+""))*100,""0.00"")&"" +/- ""&TEXT(VALUE(REGEXEXTRACT(F17,""[0-9]*\.?[0-9]+$""))*100,""0.00"")"),"79.31 +/- 0.48") -> 79.31 +/- 0.48 | O17: =IFERROR(__xludf.DUMMYFUNCTION("TEXT(VALUE(REGEXEXTRACT(G17,""^[+-]?[0-9]*\.?[0-9]+""))*100,""0.00"")&"" +/- ""&TEXT(VALUE(REGEXEXTRACT(G17,""[0-9]*\.?[0-9]+$""))*100,""0.00"")"),"79.59 +/- 0.72") -> 79.59 +/- 0.72 | P17: =IFERROR(__xludf.DUMMYFUNCTION("TEXT(VALUE(REGEXEXTRACT(H17,""^[+-]?[0-9]*\.?[0-9]+""))*100,""0.00"")&"" +/- ""&TEXT(VALUE(REGEXEXTRACT(H17,""[0-9]*\.?[0-9]+$""))*100,""0.00"")"),"77.27 +/- 1.30") -> 77.27 +/- 1.30
A18: PC3→PC4 | B18: 0.7281 +/- 0.0086 | C18: 0.7087 +/- 0.0116 | D18: 0.6712 +/- 0.0097 | E18: 0.7485 +/- 0.0109 | F18: 0.7627 +/- 0.0054 | G18: 0.7600 +/- 0.0090 | H18: 0.5693 +/- 0.0305 | I18: =A18 -> PC3→PC4 | J18: =IFERROR(__xludf.DUMMYFUNCTION("TEXT(VALUE(REGEXEXTRACT(B18,""^[+-]?[0-9]*\.?[0-9]+""))*100,""0.00"")&"" +/- ""&TEXT(VALUE(REGEXEXTRACT(B18,""[0-9]*\.?[0-9]+$""))*100,""0.00"")"),"72.81 +/- 0.86") -> 72.81 +/- 0.86 | K18: =IFERROR(__xludf.DUMMYFUNCTION("TEXT(VALUE(REGEXEXTRACT(C18,""^[+-]?[0-9]*\.?[0-9]+""))*100,""0.00"")&"" +/- ""&TEXT(VALUE(REGEXEXTRACT(C18,""[0-9]*\.?[0-9]+$""))*100,""0.00"")"),"70.87 +/- 1.16") -> 70.87 +/- 1.16 | L18: =IFERROR(__xludf.DUMMYFUNCTION("TEXT(VALUE(REGEXEXTRACT(D18,""^[+-]?[0-9]*\.?[0-9]+""))*100,""0.00"")&"" +/- ""&TEXT(VALUE(REGEXEXTRACT(D18,""[0-9]*\.?[0-9]+$""))*100,""0.00"")"),"67.12 +/- 0.97") -> 67.12 +/- 0.97 | M18: =IFERROR(__xludf.DUMMYFUNCTION("TEXT(VALUE(REGEXEXTRACT(E18,""^[+-]?[0-9]*\.?[0-9]+""))*100,""0.00"")&"" +/- ""&TEXT(VALUE(REGEXEXTRACT(E18,""[0-9]*\.?[0-9]+$""))*100,""0.00"")"),"74.85 +/- 1.09") -> 74.85 +/- 1.09 | N18: =IFERROR(__xludf.DUMMYFUNCTION("TEXT(VALUE(REGEXEXTRACT(F18,""^[+-]?[0-9]*\.?[0-9]+""))*100,""0.00"")&"" +/- ""&TEXT(VALUE(REGEXEXTRACT(F18,""[0-9]*\.?[0-9]+$""))*100,""0.00"")"),"76.27 +/- 0.54") -> 76.27 +/- 0.54 | O18: =IFERROR(__xludf.DUMMYFUNCTION("TEXT(VALUE(REGEXEXTRACT(G18,""^[+-]?[0-9]*\.?[0-9]+""))*100,""0.00"")&"" +/- ""&TEXT(VALUE(REGEXEXTRACT(G18,""[0-9]*\.?[0-9]+$""))*100,""0.00"")"),"76.00 +/- 0.90") -> 76.00 +/- 0.90 | P18: =IFERROR(__xludf.DUMMYFUNCTION("TEXT(VALUE(REGEXEXTRACT(H18,""^[+-]?[0-9]*\.?[0-9]+""))*100,""0.00"")&"" +/- ""&TEXT(VALUE(REGEXEXTRACT(H18,""[0-9]*\.?[0-9]+$""))*100,""0.00"")"),"56.93 +/- 3.05") -> 56.93 +/- 3.05
A19: PC4→CM1 | B19: 0.5959 +/- 0.0145 | C19: 0.5794 +/- 0.0186 | D19: 0.6266 +/- 0.0144 | E19: 0.6019 +/- 0.0153 | F19: 0.6004 +/- 0.0144 | G19: 0.6034 +/- 0.0148 | H19: 0.5702 +/- 0.0179 | I19: =A19 -> PC4→CM1 | J19: =IFERROR(__xludf.DUMMYFUNCTION("TEXT(VALUE(REGEXEXTRACT(B19,""^[+-]?[0-9]*\.?[0-9]+""))*100,""0.00"")&"" +/- ""&TEXT(VALUE(REGEXEXTRACT(B19,""[0-9]*\.?[0-9]+$""))*100,""0.00"")"),"59.59 +/- 1.45") -> 59.59 +/- 1.45 | K19: =IFERROR(__xludf.DUMMYFUNCTION("TEXT(VALUE(REGEXEXTRACT(C19,""^[+-]?[0-9]*\.?[0-9]+""))*100,""0.00"")&"" +/- ""&TEXT(VALUE(REGEXEXTRACT(C19,""[0-9]*\.?[0-9]+$""))*100,""0.00"")"),"57.94 +/- 1.86") -> 57.94 +/- 1.86 | L19: =IFERROR(__xludf.DUMMYFUNCTION("TEXT(VALUE(REGEXEXTRACT(D19,""^[+-]?[0-9]*\.?[0-9]+""))*100,""0.00"")&"" +/- ""&TEXT(VALUE(REGEXEXTRACT(D19,""[0-9]*\.?[0-9]+$""))*100,""0.00"")"),"62.66 +/- 1.44") -> 62.66 +/- 1.44 | M19: =IFERROR(__xludf.DUMMYFUNCTION("TEXT(VALUE(REGEXEXTRACT(E19,""^[+-]?[0-9]*\.?[0-9]+""))*100,""0.00"")&"" +/- ""&TEXT(VALUE(REGEXEXTRACT(E19,""[0-9]*\.?[0-9]+$""))*100,""0.00"")"),"60.19 +/- 1.53") -> 60.19 +/- 1.53 | N19: =IFERROR(__xludf.DUMMYFUNCTION("TEXT(VALUE(REGEXEXTRACT(F19,""^[+-]?[0-9]*\.?[0-9]+""))*100,""0.00"")&"" +/- ""&TEXT(VALUE(REGEXEXTRACT(F19,""[0-9]*\.?[0-9]+$""))*100,""0.00"")"),"60.04 +/- 1.44") -> 60.04 +/- 1.44 | O19: =IFERROR(__xludf.DUMMYFUNCTION("TEXT(VALUE(REGEXEXTRACT(G19,""^[+-]?[0-9]*\.?[0-9]+""))*100,""0.00"")&"" +/- ""&TEXT(VALUE(REGEXEXTRACT(G19,""[0-9]*\.?[0-9]+$""))*100,""0.00"")"),"60.34 +/- 1.48") -> 60.34 +/- 1.48 | P19: =IFERROR(__xludf.DUMMYFUNCTION("TEXT(VALUE(REGEXEXTRACT(H19,""^[+-]?[0-9]*\.?[0-9]+""))*100,""0.00"")&"" +/- ""&TEXT(VALUE(REGEXEXTRACT(H19,""[0-9]*\.?[0-9]+$""))*100,""0.00"")"),"57.02 +/- 1.79") -> 57.02 +/- 1.79
A20: PC4→MW1 | B20: 0.6850 +/- 0.0151 | C20: 0.5361 +/- 0.0217 | D20: 0.7447 +/- 0.0201 | E20: 0.6593 +/- 0.0184 | F20: 0.6844 +/- 0.0184 | G20: 0.6914 +/- 0.0172 | H20: 0.3902 +/- 0.0132 | I20: =A20 -> PC4→MW1 | J20: =IFERROR(__xludf.DUMMYFUNCTION("TEXT(VALUE(REGEXEXTRACT(B20,""^[+-]?[0-9]*\.?[0-9]+""))*100,""0.00"")&"" +/- ""&TEXT(VALUE(REGEXEXTRACT(B20,""[0-9]*\.?[0-9]+$""))*100,""0.00"")"),"68.50 +/- 1.51") -> 68.50 +/- 1.51 | K20: =IFERROR(__xludf.DUMMYFUNCTION("TEXT(VALUE(REGEXEXTRACT(C20,""^[+-]?[0-9]*\.?[0-9]+""))*100,""0.00"")&"" +/- ""&TEXT(VALUE(REGEXEXTRACT(C20,""[0-9]*\.?[0-9]+$""))*100,""0.00"")"),"53.61 +/- 2.17") -> 53.61 +/- 2.17 | L20: =IFERROR(__xludf.DUMMYFUNCTION("TEXT(VALUE(REGEXEXTRACT(D20,""^[+-]?[0-9]*\.?[0-9]+""))*100,""0.00"")&"" +/- ""&TEXT(VALUE(REGEXEXTRACT(D20,""[0-9]*\.?[0-9]+$""))*100,""0.00"")"),"74.47 +/- 2.01") -> 74.47 +/- 2.01 | M20: =IFERROR(__xludf.DUMMYFUNCTION("TEXT(VALUE(REGEXEXTRACT(E20,""^[+-]?[0-9]*\.?[0-9]+""))*100,""0.00"")&"" +/- ""&TEXT(VALUE(REGEXEXTRACT(E20,""[0-9]*\.?[0-9]+$""))*100,""0.00"")"),"65.93 +/- 1.84") -> 65.93 +/- 1.84 | N20: =IFERROR(__xludf.DUMMYFUNCTION("TEXT(VALUE(REGEXEXTRACT(F20,""^[+-]?[0-9]*\.?[0-9]+""))*100,""0.00"")&"" +/- ""&TEXT(VALUE(REGEXEXTRACT(F20,""[0-9]*\.?[0-9]+$""))*100,""0.00"")"),"68.44 +/- 1.84") -> 68.44 +/- 1.84 | O20: =IFERROR(__xludf.DUMMYFUNCTION("TEXT(VALUE(REGEXEXTRACT(G20,""^[+-]?[0-9]*\.?[0-9]+""))*100,""0.00"")&"" +/- ""&TEXT(VALUE(REGEXEXTRACT(G20,""[0-9]*\.?[0-9]+$""))*100,""0.00"")"),"69.14 +/- 1.72") -> 69.14 +/- 1.72 | P20: =IFERROR(__xludf.DUMMYFUNCTION("TEXT(VALUE(REGEXEXTRACT(H20,""^[+-]?[0-9]*\.?[0-9]+""))*100,""0.00"")&"" +/- ""&TEXT(VALUE(REGEXEXTRACT(H20,""[0-9]*\.?[0-9]+$""))*100,""0.00"")"),"39.02 +/- 1.32") -> 39.02 +/- 1.32
A21: PC4→PC1 | B21: 0.7764 +/- 0.0084 | C21: 0.7919 +/- 0.0120 | D21: 0.7655 +/- 0.0118 | E21: 0.7969 +/- 0.0103 | F21: 0.7724 +/- 0.0119 | G21: 0.7889 +/- 0.0142 | H21: 0.7690 +/- 0.0119 | I21: =A21 -> PC4→PC1 | J21: =IFERROR(__xludf.DUMMYFUNCTION("TEXT(VALUE(REGEXEXTRACT(B21,""^[+-]?[0-9]*\.?[0-9]+""))*100,""0.00"")&"" +/- ""&TEXT(VALUE(REGEXEXTRACT(B21,""[0-9]*\.?[0-9]+$""))*100,""0.00"")"),"77.64 +/- 0.84") -> 77.64 +/- 0.84 | K21: =IFERROR(__xludf.DUMMYFUNCTION("TEXT(VALUE(REGEXEXTRACT(C21,""^[+-]?[0-9]*\.?[0-9]+""))*100,""0.00"")&"" +/- ""&TEXT(VALUE(REGEXEXTRACT(C21,""[0-9]*\.?[0-9]+$""))*100,""0.00"")"),"79.19 +/- 1.20") -> 79.19 +/- 1.20 | L21: =IFERROR(__xludf.DUMMYFUNCTION("TEXT(VALUE(REGEXEXTRACT(D21,""^[+-]?[0-9]*\.?[0-9]+""))*100,""0.00"")&"" +/- ""&TEXT(VALUE(REGEXEXTRACT(D21,""[0-9]*\.?[0-9]+$""))*100,""0.00"")"),"76.55 +/- 1.18") -> 76.55 +/- 1.18 | M21: =IFERROR(__xludf.DUMMYFUNCTION("TEXT(VALUE(REGEXEXTRACT(E21,""^[+-]?[0-9]*\.?[0-9]+""))*100,""0.00"")&"" +/- ""&TEXT(VALUE(REGEXEXTRACT(E21,""[0-9]*\.?[0-9]+$""))*100,""0.00"")"),"79.69 +/- 1.03") -> 79.69 +/- 1.03 | N21: =IFERROR(__xludf.DUMMYFUNCTION("TEXT(VALUE(REGEXEXTRACT(F21,""^[+-]?[0-9]*\.?[0-9]+""))*100,""0.00"")&"" +/- ""&TEXT(VALUE(REGEXEXTRACT(F21,""[0-9]*\.?[0-9]+$""))*100,""0.00"")"),"77.24 +/- 1.19") -> 77.24 +/- 1.19 | O21: =IFERROR(__xludf.DUMMYFUNCTION("TEXT(VALUE(REGEXEXTRACT(G21,""^[+-]?[0-9]*\.?[0-9]+""))*100,""0.00"")&"" +/- ""&TEXT(VALUE(REGEXEXTRACT(G21,""[0-9]*\.?[0-9]+$""))*100,""0.00"")"),"78.89 +/- 1.42") -> 78.89 +/- 1.42 | P21: =IFERROR(__xludf.DUMMYFUNCTION("TEXT(VALUE(REGEXEXTRACT(H21,""^[+-]?[0-9]*\.?[0-9]+""))*100,""0.00"")&"" +/- ""&TEXT(VALUE(REGEXEXTRACT(H21,""[0-9]*\.?[0-9]+$""))*100,""0.00"")"),"76.90 +/- 1.19") -> 76.90 +/- 1.19
A22: PC4→PC3 | B22: 0.7962 +/- 0.0062 | C22: 0.7658 +/- 0.0082 | D22: 0.7128 +/- 0.0084 | E22: 0.7425 +/- 0.0079 | F22: 0.7234 +/- 0.0063 | G22: 0.7362 +/- 0.0060 | H22: 0.7314 +/- 0.0133 | I22: =A22 -> PC4→PC3 | J22: =IFERROR(__xludf.DUMMYFUNCTION("TEXT(VALUE(REGEXEXTRACT(B22,""^[+-]?[0-9]*\.?[0-9]+""))*100,""0.00"")&"" +/- ""&TEXT(VALUE(REGEXEXTRACT(B22,""[0-9]*\.?[0-9]+$""))*100,""0.00"")"),"79.62 +/- 0.62") -> 79.62 +/- 0.62 | K22: =IFERROR(__xludf.DUMMYFUNCTION("TEXT(VALUE(REGEXEXTRACT(C22,""^[+-]?[0-9]*\.?[0-9]+""))*100,""0.00"")&"" +/- ""&TEXT(VALUE(REGEXEXTRACT(C22,""[0-9]*\.?[0-9]+$""))*100,""0.00"")"),"76.58 +/- 0.82") -> 76.58 +/- 0.82 | L22: =IFERROR(__xludf.DUMMYFUNCTION("TEXT(VALUE(REGEXEXTRACT(D22,""^[+-]?[0-9]*\.?[0-9]+""))*100,""0.00"")&"" +/- ""&TEXT(VALUE(REGEXEXTRACT(D22,""[0-9]*\.?[0-9]+$""))*100,""0.00"")"),"71.28 +/- 0.84") -> 71.28 +/- 0.84 | M22: =IFERROR(__xludf.DUMMYFUNCTION("TEXT(VALUE(REGEXEXTRACT(E22,""^[+-]?[0-9]*\.?[0-9]+""))*100,""0.00"")&"" +/- ""&TEXT(VALUE(REGEXEXTRACT(E22,""[0-9]*\.?[0-9]+$""))*100,""0.00"")"),"74.25 +/- 0.79") -> 74.25 +/- 0.79 | N22: =IFERROR(__xludf.DUMMYFUNCTION("TEXT(VALUE(REGEXEXTRACT(F22,""^[+-]?[0-9]*\.?[0-9]+""))*100,""0.00"")&"" +/- ""&TEXT(VALUE(REGEXEXTRACT(F22,""[0-9]*\.?[0-9]+$""))*100,""0.00"")"),"72.34 +/- 0.63") -> 72.34 +/- 0.63 | O22: =IFERROR(__xludf.DUMMYFUNCTION("TEXT(VALUE(REGEXEXTRACT(G22,""^[+-]?[0-9]*\.?[0-9]+""))*100,""0.00"")&"" +/- ""&TEXT(VALUE(REGEXEXTRACT(G22,""[0-9]*\.?[0-9]+$""))*100,""0.00"")"),"73.62 +/- 0.60") -> 73.62 +/- 0.60 | P22: =IFERROR(__xludf.DUMMYFUNCTION("TEXT(VALUE(REGEXEXTRACT(H22,""^[+-]?[0-9]*\.?[0-9]+""))*100,""0.00"")&"" +/- ""&TEXT(VALUE(REGEXEXTRACT(H22,""[0-9]*\.?[0-9]+$""))*100,""0.00"")"),"73.14 +/- 1.33") -> 73.14 +/- 1.33
A23: W/T/L | C23: 16/0/4 | D23: 14/0/6 | E23: 9/0/11 | F23: 8/0/12 | G23: 5/0/15 | H23: 19/0/1 | I23: =A23 -> W/T/L | K23: =IFERROR(__xludf.DUMMYFUNCTION("SUM(ARRAYFORMULA(IFERROR( (VALUE(REGEXEXTRACT($J$3:$J$22,""^[+-]?[0-9]*\.?[0-9]+""))> VALUE(REGEXEXTRACT(K$3:K$22,""^[+-]?[0-9]*\.?[0-9]+"")))*1,0))) &""/""& SUM(ARRAYFORMULA(IFERROR( (VALUE(REGEXEXTRACT($J$3:$J$22,""^[+-]?[0-9]*\.?[0-9]+""))= V"&"ALUE(REGEXEXTRACT(K$3:K$22,""^[+-]?[0-9]*\.?[0-9]+"")))*1,0))) &""/""& SUM(ARRAYFORMULA(IFERROR( (VALUE(REGEXEXTRACT($J$3:$J$22,""^[+-]?[0-9]*\.?[0-9]+""))< VALUE(REGEXEXTRACT(K$3:K$22,""^[+-]?[0-9]*\.?[0-9]+"")))*1,0)))"),"16/0/4") -> 16/0/4 | L23: =IFERROR(__xludf.DUMMYFUNCTION("SUM(ARRAYFORMULA(IFERROR( (VALUE(REGEXEXTRACT($J$3:$J$22,""^[+-]?[0-9]*\.?[0-9]+""))> VALUE(REGEXEXTRACT(L$3:L$22,""^[+-]?[0-9]*\.?[0-9]+"")))*1,0))) &""/""& SUM(ARRAYFORMULA(IFERROR( (VALUE(REGEXEXTRACT($J$3:$J$22,""^[+-]?[0-9]*\.?[0-9]+""))= V"&"ALUE(REGEXEXTRACT(L$3:L$22,""^[+-]?[0-9]*\.?[0-9]+"")))*1,0))) &""/""& SUM(ARRAYFORMULA(IFERROR( (VALUE(REGEXEXTRACT($J$3:$J$22,""^[+-]?[0-9]*\.?[0-9]+""))< VALUE(REGEXEXTRACT(L$3:L$22,""^[+-]?[0-9]*\.?[0-9]+"")))*1,0)))"),"14/0/6") -> 14/0/6 | M23: =IFERROR(__xludf.DUMMYFUNCTION("SUM(ARRAYFORMULA(IFERROR( (VALUE(REGEXEXTRACT($J$3:$J$22,""^[+-]?[0-9]*\.?[0-9]+""))> VALUE(REGEXEXTRACT(M$3:M$22,""^[+-]?[0-9]*\.?[0-9]+"")))*1,0))) &""/""& SUM(ARRAYFORMULA(IFERROR( (VALUE(REGEXEXTRACT($J$3:$J$22,""^[+-]?[0-9]*\.?[0-9]+""))= V"&"ALUE(REGEXEXTRACT(M$3:M$22,""^[+-]?[0-9]*\.?[0-9]+"")))*1,0))) &""/""& SUM(ARRAYFORMULA(IFERROR( (VALUE(REGEXEXTRACT($J$3:$J$22,""^[+-]?[0-9]*\.?[0-9]+""))< VALUE(REGEXEXTRACT(M$3:M$22,""^[+-]?[0-9]*\.?[0-9]+"")))*1,0)))"),"9/0/11") -> 9/0/11 | N23: =IFERROR(__xludf.DUMMYFUNCTION("SUM(ARRAYFORMULA(IFERROR( (VALUE(REGEXEXTRACT($J$3:$J$22,""^[+-]?[0-9]*\.?[0-9]+""))> VALUE(REGEXEXTRACT(N$3:N$22,""^[+-]?[0-9]*\.?[0-9]+"")))*1,0))) &""/""& SUM(ARRAYFORMULA(IFERROR( (VALUE(REGEXEXTRACT($J$3:$J$22,""^[+-]?[0-9]*\.?[0-9]+""))= V"&"ALUE(REGEXEXTRACT(N$3:N$22,""^[+-]?[0-9]*\.?[0-9]+"")))*1,0))) &""/""& SUM(ARRAYFORMULA(IFERROR( (VALUE(REGEXEXTRACT($J$3:$J$22,""^[+-]?[0-9]*\.?[0-9]+""))< VALUE(REGEXEXTRACT(N$3:N$22,""^[+-]?[0-9]*\.?[0-9]+"")))*1,0)))"),"8/0/12") -> 8/0/12 | O23: =IFERROR(__xludf.DUMMYFUNCTION("SUM(ARRAYFORMULA(IFERROR( (VALUE(REGEXEXTRACT($J$3:$J$22,""^[+-]?[0-9]*\.?[0-9]+""))> VALUE(REGEXEXTRACT(O$3:O$22,""^[+-]?[0-9]*\.?[0-9]+"")))*1,0))) &""/""& SUM(ARRAYFORMULA(IFERROR( (VALUE(REGEXEXTRACT($J$3:$J$22,""^[+-]?[0-9]*\.?[0-9]+""))= V"&"ALUE(REGEXEXTRACT(O$3:O$22,""^[+-]?[0-9]*\.?[0-9]+"")))*1,0))) &""/""& SUM(ARRAYFORMULA(IFERROR( (VALUE(REGEXEXTRACT($J$3:$J$22,""^[+-]?[0-9]*\.?[0-9]+""))< VALUE(REGEXEXTRACT(O$3:O$22,""^[+-]?[0-9]*\.?[0-9]+"")))*1,0)))"),"5/0/15") -> 5/0/15 | P23: =IFERROR(__xludf.DUMMYFUNCTION("SUM(ARRAYFORMULA(IFERROR( (VALUE(REGEXEXTRACT($J$3:$J$22,""^[+-]?[0-9]*\.?[0-9]+""))> VALUE(REGEXEXTRACT(P$3:P$22,""^[+-]?[0-9]*\.?[0-9]+"")))*1,0))) &""/""& SUM(ARRAYFORMULA(IFERROR( (VALUE(REGEXEXTRACT($J$3:$J$22,""^[+-]?[0-9]*\.?[0-9]+""))= V"&"ALUE(REGEXEXTRACT(P$3:P$22,""^[+-]?[0-9]*\.?[0-9]+"")))*1,0))) &""/""& SUM(ARRAYFORMULA(IFERROR( (VALUE(REGEXEXTRACT($J$3:$J$22,""^[+-]?[0-9]*\.?[0-9]+""))< VALUE(REGEXEXTRACT(P$3:P$22,""^[+-]?[0-9]*\.?[0-9]+"")))*1,0)))"),"19/0/1") -> 19/0/1
A24: Average (%) | B24: 72.65 | C24: 68.94 | D24: 68.87 | E24: 71.82 | F24: 71.26 | G24: 71.72 | H24: 61.23 | I24: =A24 -> Average (%) | J24: =IFERROR(__xludf.DUMMYFUNCTION("ROUND(AVERAGE(ARRAYFORMULA(IFERROR(VALUE(REGEXEXTRACT(J$3:J$22,""^[+-]?[0-9]*\.?[0-9]+"")),""""))),2)"),72.65) -> 72.65 | K24: =IFERROR(__xludf.DUMMYFUNCTION("ROUND(AVERAGE(ARRAYFORMULA(IFERROR(VALUE(REGEXEXTRACT(K$3:K$22,""^[+-]?[0-9]*\.?[0-9]+"")),""""))),2)"),68.94) -> 68.94 | L24: =IFERROR(__xludf.DUMMYFUNCTION("ROUND(AVERAGE(ARRAYFORMULA(IFERROR(VALUE(REGEXEXTRACT(L$3:L$22,""^[+-]?[0-9]*\.?[0-9]+"")),""""))),2)"),68.87) -> 68.87 | M24: =IFERROR(__xludf.DUMMYFUNCTION("ROUND(AVERAGE(ARRAYFORMULA(IFERROR(VALUE(REGEXEXTRACT(M$3:M$22,""^[+-]?[0-9]*\.?[0-9]+"")),""""))),2)"),71.82) -> 71.82 | N24: =IFERROR(__xludf.DUMMYFUNCTION("ROUND(AVERAGE(ARRAYFORMULA(IFERROR(VALUE(REGEXEXTRACT(N$3:N$22,""^[+-]?[0-9]*\.?[0-9]+"")),""""))),2)"),71.26) -> 71.26 | O24: =IFERROR(__xludf.DUMMYFUNCTION("ROUND(AVERAGE(ARRAYFORMULA(IFERROR(VALUE(REGEXEXTRACT(O$3:O$22,""^[+-]?[0-9]*\.?[0-9]+"")),""""))),2)"),71.72) -> 71.72 | P24: =IFERROR(__xludf.DUMMYFUNCTION("ROUND(AVERAGE(ARRAYFORMULA(IFERROR(VALUE(REGEXEXTRACT(P$3:P$22,""^[+-]?[0-9]*\.?[0-9]+"")),""""))),2)"),61.23) -> 61.23
A25: RELINK | I25: RELINK
A26: A→S | B26: 0.8130 +/- 0.0195 | C26: 0.8130 +/- 0.0195 | D26: 0.6758 +/- 0.0474 | E26: 0.8130 +/- 0.0195 | F26: 0.8130 +/- 0.0195 | G26: 0.8130 +/- 0.0195 | H26: 0.8130 +/- 0.0195 | I26: =A26 -> A→S | J26: =IFERROR(__xludf.DUMMYFUNCTION("TEXT(VALUE(REGEXEXTRACT(B26,""^[+-]?[0-9]*\.?[0-9]+""))*100,""0.00"")&"" +/- ""&TEXT(VALUE(REGEXEXTRACT(B26,""[0-9]*\.?[0-9]+$""))*100,""0.00"")"),"81.30 +/- 1.95") -> 81.30 +/- 1.95 | K26: =IFERROR(__xludf.DUMMYFUNCTION("TEXT(VALUE(REGEXEXTRACT(C26,""^[+-]?[0-9]*\.?[0-9]+""))*100,""0.00"")&"" +/- ""&TEXT(VALUE(REGEXEXTRACT(C26,""[0-9]*\.?[0-9]+$""))*100,""0.00"")"),"81.30 +/- 1.95") -> 81.30 +/- 1.95 | L26: =IFERROR(__xludf.DUMMYFUNCTION("TEXT(VALUE(REGEXEXTRACT(D26,""^[+-]?[0-9]*\.?[0-9]+""))*100,""0.00"")&"" +/- ""&TEXT(VALUE(REGEXEXTRACT(D26,""[0-9]*\.?[0-9]+$""))*100,""0.00"")"),"67.58 +/- 4.74") -> 67.58 +/- 4.74 | M26: =IFERROR(__xludf.DUMMYFUNCTION("TEXT(VALUE(REGEXEXTRACT(E26,""^[+-]?[0-9]*\.?[0-9]+""))*100,""0.00"")&"" +/- ""&TEXT(VALUE(REGEXEXTRACT(E26,""[0-9]*\.?[0-9]+$""))*100,""0.00"")"),"81.30 +/- 1.95") -> 81.30 +/- 1.95 | N26: =IFERROR(__xludf.DUMMYFUNCTION("TEXT(VALUE(REGEXEXTRACT(F26,""^[+-]?[0-9]*\.?[0-9]+""))*100,""0.00"")&"" +/- ""&TEXT(VALUE(REGEXEXTRACT(F26,""[0-9]*\.?[0-9]+$""))*100,""0.00"")"),"81.30 +/- 1.95") -> 81.30 +/- 1.95 | O26: =IFERROR(__xludf.DUMMYFUNCTION("TEXT(VALUE(REGEXEXTRACT(G26,""^[+-]?[0-9]*\.?[0-9]+""))*100,""0.00"")&"" +/- ""&TEXT(VALUE(REGEXEXTRACT(G26,""[0-9]*\.?[0-9]+$""))*100,""0.00"")"),"81.30 +/- 1.95") -> 81.30 +/- 1.95 | P26: =IFERROR(__xludf.DUMMYFUNCTION("TEXT(VALUE(REGEXEXTRACT(H26,""^[+-]?[0-9]*\.?[0-9]+""))*100,""0.00"")&"" +/- ""&TEXT(VALUE(REGEXEXTRACT(H26,""[0-9]*\.?[0-9]+$""))*100,""0.00"")"),"81.30 +/- 1.95") -> 81.30 +/- 1.95
A27: A→Z | B27: 0.6422 +/- 0.0115 | C27: 0.6422 +/- 0.0115 | D27: 0.5664 +/- 0.0329 | E27: 0.6422 +/- 0.0115 | F27: 0.6422 +/- 0.0115 | G27: 0.6422 +/- 0.0115 | H27: 0.6422 +/- 0.0115 | I27: =A27 -> A→Z | J27: =IFERROR(__xludf.DUMMYFUNCTION("TEXT(VALUE(REGEXEXTRACT(B27,""^[+-]?[0-9]*\.?[0-9]+""))*100,""0.00"")&"" +/- ""&TEXT(VALUE(REGEXEXTRACT(B27,""[0-9]*\.?[0-9]+$""))*100,""0.00"")"),"64.22 +/- 1.15") -> 64.22 +/- 1.15 | K27: =IFERROR(__xludf.DUMMYFUNCTION("TEXT(VALUE(REGEXEXTRACT(C27,""^[+-]?[0-9]*\.?[0-9]+""))*100,""0.00"")&"" +/- ""&TEXT(VALUE(REGEXEXTRACT(C27,""[0-9]*\.?[0-9]+$""))*100,""0.00"")"),"64.22 +/- 1.15") -> 64.22 +/- 1.15 | L27: =IFERROR(__xludf.DUMMYFUNCTION("TEXT(VALUE(REGEXEXTRACT(D27,""^[+-]?[0-9]*\.?[0-9]+""))*100,""0.00"")&"" +/- ""&TEXT(VALUE(REGEXEXTRACT(D27,""[0-9]*\.?[0-9]+$""))*100,""0.00"")"),"56.64 +/- 3.29") -> 56.64 +/- 3.29 | M27: =IFERROR(__xludf.DUMMYFUNCTION("TEXT(VALUE(REGEXEXTRACT(E27,""^[+-]?[0-9]*\.?[0-9]+""))*100,""0.00"")&"" +/- ""&TEXT(VALUE(REGEXEXTRACT(E27,""[0-9]*\.?[0-9]+$""))*100,""0.00"")"),"64.22 +/- 1.15") -> 64.22 +/- 1.15 | N27: =IFERROR(__xludf.DUMMYFUNCTION("TEXT(VALUE(REGEXEXTRACT(F27,""^[+-]?[0-9]*\.?[0-9]+""))*100,""0.00"")&"" +/- ""&TEXT(VALUE(REGEXEXTRACT(F27,""[0-9]*\.?[0-9]+$""))*100,""0.00"")"),"64.22 +/- 1.15") -> 64.22 +/- 1.15 | O27: =IFERROR(__xludf.DUMMYFUNCTION("TEXT(VALUE(REGEXEXTRACT(G27,""^[+-]?[0-9]*\.?[0-9]+""))*100,""0.00"")&"" +/- ""&TEXT(VALUE(REGEXEXTRACT(G27,""[0-9]*\.?[0-9]+$""))*100,""0.00"")"),"64.22 +/- 1.15") -> 64.22 +/- 1.15 | P27: =IFERROR(__xludf.DUMMYFUNCTION("TEXT(VALUE(REGEXEXTRACT(H27,""^[+-]?[0-9]*\.?[0-9]+""))*100,""0.00"")&"" +/- ""&TEXT(VALUE(REGEXEXTRACT(H27,""[0-9]*\.?[0-9]+$""))*100,""0.00"")"),"64.22 +/- 1.15") -> 64.22 +/- 1.15
A28: S→A | B28: 0.7747 +/- 0.0072 | C28: 0.7765 +/- 0.0053 | D28: 0.6399 +/- 0.0211 | E28: 0.7742 +/- 0.0108 | F28: 0.7798 +/- 0.0074 | G28: 0.7762 +/- 0.0073 | H28: 0.7537 +/- 0.0127 | I28: =A28 -> S→A | J28: =IFERROR(__xludf.DUMMYFUNCTION("TEXT(VALUE(REGEXEXTRACT(B28,""^[+-]?[0-9]*\.?[0-9]+""))*100,""0.00"")&"" +/- ""&TEXT(VALUE(REGEXEXTRACT(B28,""[0-9]*\.?[0-9]+$""))*100,""0.00"")"),"77.47 +/- 0.72") -> 77.47 +/- 0.72 | K28: =IFERROR(__xludf.DUMMYFUNCTION("TEXT(VALUE(REGEXEXTRACT(C28,""^[+-]?[0-9]*\.?[0-9]+""))*100,""0.00"")&"" +/- ""&TEXT(VALUE(REGEXEXTRACT(C28,""[0-9]*\.?[0-9]+$""))*100,""0.00"")"),"77.65 +/- 0.53") -> 77.65 +/- 0.53 | L28: =IFERROR(__xludf.DUMMYFUNCTION("TEXT(VALUE(REGEXEXTRACT(D28,""^[+-]?[0-9]*\.?[0-9]+""))*100,""0.00"")&"" +/- ""&TEXT(VALUE(REGEXEXTRACT(D28,""[0-9]*\.?[0-9]+$""))*100,""0.00"")"),"63.99 +/- 2.11") -> 63.99 +/- 2.11 | M28: =IFERROR(__xludf.DUMMYFUNCTION("TEXT(VALUE(REGEXEXTRACT(E28,""^[+-]?[0-9]*\.?[0-9]+""))*100,""0.00"")&"" +/- ""&TEXT(VALUE(REGEXEXTRACT(E28,""[0-9]*\.?[0-9]+$""))*100,""0.00"")"),"77.42 +/- 1.08") -> 77.42 +/- 1.08 | N28: =IFERROR(__xludf.DUMMYFUNCTION("TEXT(VALUE(REGEXEXTRACT(F28,""^[+-]?[0-9]*\.?[0-9]+""))*100,""0.00"")&"" +/- ""&TEXT(VALUE(REGEXEXTRACT(F28,""[0-9]*\.?[0-9]+$""))*100,""0.00"")"),"77.98 +/- 0.74") -> 77.98 +/- 0.74 | O28: =IFERROR(__xludf.DUMMYFUNCTION("TEXT(VALUE(REGEXEXTRACT(G28,""^[+-]?[0-9]*\.?[0-9]+""))*100,""0.00"")&"" +/- ""&TEXT(VALUE(REGEXEXTRACT(G28,""[0-9]*\.?[0-9]+$""))*100,""0.00"")"),"77.62 +/- 0.73") -> 77.62 +/- 0.73 | P28: =IFERROR(__xludf.DUMMYFUNCTION("TEXT(VALUE(REGEXEXTRACT(H28,""^[+-]?[0-9]*\.?[0-9]+""))*100,""0.00"")&"" +/- ""&TEXT(VALUE(REGEXEXTRACT(H28,""[0-9]*\.?[0-9]+$""))*100,""0.00"")"),"75.37 +/- 1.27") -> 75.37 +/- 1.27
A29: S→Z | B29: 0.6363 +/- 0.0055 | C29: 0.6375 +/- 0.0052 | D29: 0.5037 +/- 0.0225 | E29: 0.6338 +/- 0.0081 | F29: 0.6421 +/- 0.0068 | G29: 0.6377 +/- 0.0080 | H29: 0.6183 +/- 0.0088 | I29: =A29 -> S→Z | J29: =IFERROR(__xludf.DUMMYFUNCTION("TEXT(VALUE(REGEXEXTRACT(B29,""^[+-]?[0-9]*\.?[0-9]+""))*100,""0.00"")&"" +/- ""&TEXT(VALUE(REGEXEXTRACT(B29,""[0-9]*\.?[0-9]+$""))*100,""0.00"")"),"63.63 +/- 0.55") -> 63.63 +/- 0.55 | K29: =IFERROR(__xludf.DUMMYFUNCTION("TEXT(VALUE(REGEXEXTRACT(C29,""^[+-]?[0-9]*\.?[0-9]+""))*100,""0.00"")&"" +/- ""&TEXT(VALUE(REGEXEXTRACT(C29,""[0-9]*\.?[0-9]+$""))*100,""0.00"")"),"63.75 +/- 0.52") -> 63.75 +/- 0.52 | L29: =IFERROR(__xludf.DUMMYFUNCTION("TEXT(VALUE(REGEXEXTRACT(D29,""^[+-]?[0-9]*\.?[0-9]+""))*100,""0.00"")&"" +/- ""&TEXT(VALUE(REGEXEXTRACT(D29,""[0-9]*\.?[0-9]+$""))*100,""0.00"")"),"50.37 +/- 2.25") -> 50.37 +/- 2.25 | M29: =IFERROR(__xludf.DUMMYFUNCTION("TEXT(VALUE(REGEXEXTRACT(E29,""^[+-]?[0-9]*\.?[0-9]+""))*100,""0.00"")&"" +/- ""&TEXT(VALUE(REGEXEXTRACT(E29,""[0-9]*\.?[0-9]+$""))*100,""0.00"")"),"63.38 +/- 0.81") -> 63.38 +/- 0.81 | N29: =IFERROR(__xludf.DUMMYFUNCTION("TEXT(VALUE(REGEXEXTRACT(F29,""^[+-]?[0-9]*\.?[0-9]+""))*100,""0.00"")&"" +/- ""&TEXT(VALUE(REGEXEXTRACT(F29,""[0-9]*\.?[0-9]+$""))*100,""0.00"")"),"64.21 +/- 0.68") -> 64.21 +/- 0.68 | O29: =IFERROR(__xludf.DUMMYFUNCTION("TEXT(VALUE(REGEXEXTRACT(G29,""^[+-]?[0-9]*\.?[0-9]+""))*100,""0.00"")&"" +/- ""&TEXT(VALUE(REGEXEXTRACT(G29,""[0-9]*\.?[0-9]+$""))*100,""0.00"")"),"63.77 +/- 0.80") -> 63.77 +/- 0.80 | P29: =IFERROR(__xludf.DUMMYFUNCTION("TEXT(VALUE(REGEXEXTRACT(H29,""^[+-]?[0-9]*\.?[0-9]+""))*100,""0.00"")&"" +/- ""&TEXT(VALUE(REGEXEXTRACT(H29,""[0-9]*\.?[0-9]+$""))*100,""0.00"")"),"61.83 +/- 0.88") -> 61.83 +/- 0.88
A30: Z→A | B30: 0.7202 +/- 0.0138 | C30: 0.6594 +/- 0.0242 | D30: 0.6190 +/- 0.0302 | E30: 0.7023 +/- 0.0194 | F30: 0.7161 +/- 0.0168 | G30: 0.7144 +/- 0.0186 | H30: 0.3925 +/- 0.0310 | I30: =A30 -> Z→A | J30: =IFERROR(__xludf.DUMMYFUNCTION("TEXT(VALUE(REGEXEXTRACT(B30,""^[+-]?[0-9]*\.?[0-9]+""))*100,""0.00"")&"" +/- ""&TEXT(VALUE(REGEXEXTRACT(B30,""[0-9]*\.?[0-9]+$""))*100,""0.00"")"),"72.02 +/- 1.38") -> 72.02 +/- 1.38 | K30: =IFERROR(__xludf.DUMMYFUNCTION("TEXT(VALUE(REGEXEXTRACT(C30,""^[+-]?[0-9]*\.?[0-9]+""))*100,""0.00"")&"" +/- ""&TEXT(VALUE(REGEXEXTRACT(C30,""[0-9]*\.?[0-9]+$""))*100,""0.00"")"),"65.94 +/- 2.42") -> 65.94 +/- 2.42 | L30: =IFERROR(__xludf.DUMMYFUNCTION("TEXT(VALUE(REGEXEXTRACT(D30,""^[+-]?[0-9]*\.?[0-9]+""))*100,""0.00"")&"" +/- ""&TEXT(VALUE(REGEXEXTRACT(D30,""[0-9]*\.?[0-9]+$""))*100,""0.00"")"),"61.90 +/- 3.02") -> 61.90 +/- 3.02 | M30: =IFERROR(__xludf.DUMMYFUNCTION("TEXT(VALUE(REGEXEXTRACT(E30,""^[+-]?[0-9]*\.?[0-9]+""))*100,""0.00"")&"" +/- ""&TEXT(VALUE(REGEXEXTRACT(E30,""[0-9]*\.?[0-9]+$""))*100,""0.00"")"),"70.23 +/- 1.94") -> 70.23 +/- 1.94 | N30: =IFERROR(__xludf.DUMMYFUNCTION("TEXT(VALUE(REGEXEXTRACT(F30,""^[+-]?[0-9]*\.?[0-9]+""))*100,""0.00"")&"" +/- ""&TEXT(VALUE(REGEXEXTRACT(F30,""[0-9]*\.?[0-9]+$""))*100,""0.00"")"),"71.61 +/- 1.68") -> 71.61 +/- 1.68 | O30: =IFERROR(__xludf.DUMMYFUNCTION("TEXT(VALUE(REGEXEXTRACT(G30,""^[+-]?[0-9]*\.?[0-9]+""))*100,""0.00"")&"" +/- ""&TEXT(VALUE(REGEXEXTRACT(G30,""[0-9]*\.?[0-9]+$""))*100,""0.00"")"),"71.44 +/- 1.86") -> 71.44 +/- 1.86 | P30: =IFERROR(__xludf.DUMMYFUNCTION("TEXT(VALUE(REGEXEXTRACT(H30,""^[+-]?[0-9]*\.?[0-9]+""))*100,""0.00"")&"" +/- ""&TEXT(VALUE(REGEXEXTRACT(H30,""[0-9]*\.?[0-9]+$""))*100,""0.00"")"),"39.25 +/- 3.10") -> 39.25 +/- 3.10
A31: Z→S | B31: 0.8534 +/- 0.0223 | C31: 0.7477 +/- 0.0318 | D31: 0.4959 +/- 0.0487 | E31: 0.8113 +/- 0.0235 | F31: 0.8170 +/- 0.0216 | G31: 0.8076 +/- 0.0167 | H31: 0.4156 +/- 0.0307 | I31: =A31 -> Z→S | J31: =IFERROR(__xludf.DUMMYFUNCTION("TEXT(VALUE(REGEXEXTRACT(B31,""^[+-]?[0-9]*\.?[0-9]+""))*100,""0.00"")&"" +/- ""&TEXT(VALUE(REGEXEXTRACT(B31,""[0-9]*\.?[0-9]+$""))*100,""0.00"")"),"85.34 +/- 2.23") -> 85.34 +/- 2.23 | K31: =IFERROR(__xludf.DUMMYFUNCTION("TEXT(VALUE(REGEXEXTRACT(C31,""^[+-]?[0-9]*\.?[0-9]+""))*100,""0.00"")&"" +/- ""&TEXT(VALUE(REGEXEXTRACT(C31,""[0-9]*\.?[0-9]+$""))*100,""0.00"")"),"74.77 +/- 3.18") -> 74.77 +/- 3.18 | L31: =IFERROR(__xludf.DUMMYFUNCTION("TEXT(VALUE(REGEXEXTRACT(D31,""^[+-]?[0-9]*\.?[0-9]+""))*100,""0.00"")&"" +/- ""&TEXT(VALUE(REGEXEXTRACT(D31,""[0-9]*\.?[0-9]+$""))*100,""0.00"")"),"49.59 +/- 4.87") -> 49.59 +/- 4.87 | M31: =IFERROR(__xludf.DUMMYFUNCTION("TEXT(VALUE(REGEXEXTRACT(E31,""^[+-]?[0-9]*\.?[0-9]+""))*100,""0.00"")&"" +/- ""&TEXT(VALUE(REGEXEXTRACT(E31,""[0-9]*\.?[0-9]+$""))*100,""0.00"")"),"81.13 +/- 2.35") -> 81.13 +/- 2.35 | N31: =IFERROR(__xludf.DUMMYFUNCTION("TEXT(VALUE(REGEXEXTRACT(F31,""^[+-]?[0-9]*\.?[0-9]+""))*100,""0.00"")&"" +/- ""&TEXT(VALUE(REGEXEXTRACT(F31,""[0-9]*\.?[0-9]+$""))*100,""0.00"")"),"81.70 +/- 2.16") -> 81.70 +/- 2.16 | O31: =IFERROR(__xludf.DUMMYFUNCTION("TEXT(VALUE(REGEXEXTRACT(G31,""^[+-]?[0-9]*\.?[0-9]+""))*100,""0.00"")&"" +/- ""&TEXT(VALUE(REGEXEXTRACT(G31,""[0-9]*\.?[0-9]+$""))*100,""0.00"")"),"80.76 +/- 1.67") -> 80.76 +/- 1.67 | P31: =IFERROR(__xludf.DUMMYFUNCTION("TEXT(VALUE(REGEXEXTRACT(H31,""^[+-]?[0-9]*\.?[0-9]+""))*100,""0.00"")&"" +/- ""&TEXT(VALUE(REGEXEXTRACT(H31,""[0-9]*\.?[0-9]+$""))*100,""0.00"")"),"41.56 +/- 3.07") -> 41.56 +/- 3.07
A32: W/T/L | C32: 2/2/2 | D32: 6/0/0 | E32: 4/2/0 | F32: 2/2/2 | G32: 2/2/2 | H32: 4/2/0 | I32: =A32 -> W/T/L | K32: =IFERROR(__xludf.DUMMYFUNCTION("SUM(ARRAYFORMULA(IFERROR( (VALUE(REGEXEXTRACT($J$26:$J$31,""^[+-]?[0-9]*\.?[0-9]+""))> VALUE(REGEXEXTRACT(K$26:K$31,""^[+-]?[0-9]*\.?[0-9]+"")))*1,0))) &""/""& SUM(ARRAYFORMULA(IFERROR( (VALUE(REGEXEXTRACT($J$26:$J$31,""^[+-]?[0-9]*\.?[0-9]+""))= "&" VALUE(REGEXEXTRACT(K$26:K$31,""^[+-]?[0-9]*\.?[0-9]+"")))*1,0))) &""/""& SUM(ARRAYFORMULA(IFERROR( (VALUE(REGEXEXTRACT($J$26:$J$31,""^[+-]?[0-9]*\.?[0-9]+""))< VALUE(REGEXEXTRACT(K$26:K$31,""^[+-]?[0-9]*\.?[0-9]+"")))*1,0)))"),"2/2/2") -> 2/2/2 | L32: =IFERROR(__xludf.DUMMYFUNCTION("SUM(ARRAYFORMULA(IFERROR( (VALUE(REGEXEXTRACT($J$26:$J$31,""^[+-]?[0-9]*\.?[0-9]+""))> VALUE(REGEXEXTRACT(L$26:L$31,""^[+-]?[0-9]*\.?[0-9]+"")))*1,0))) &""/""& SUM(ARRAYFORMULA(IFERROR( (VALUE(REGEXEXTRACT($J$26:$J$31,""^[+-]?[0-9]*\.?[0-9]+""))= "&" VALUE(REGEXEXTRACT(L$26:L$31,""^[+-]?[0-9]*\.?[0-9]+"")))*1,0))) &""/""& SUM(ARRAYFORMULA(IFERROR( (VALUE(REGEXEXTRACT($J$26:$J$31,""^[+-]?[0-9]*\.?[0-9]+""))< VALUE(REGEXEXTRACT(L$26:L$31,""^[+-]?[0-9]*\.?[0-9]+"")))*1,0)))"),"6/0/0") -> 6/0/0 | M32: =IFERROR(__xludf.DUMMYFUNCTION("SUM(ARRAYFORMULA(IFERROR( (VALUE(REGEXEXTRACT($J$26:$J$31,""^[+-]?[0-9]*\.?[0-9]+""))> VALUE(REGEXEXTRACT(M$26:M$31,""^[+-]?[0-9]*\.?[0-9]+"")))*1,0))) &""/""& SUM(ARRAYFORMULA(IFERROR( (VALUE(REGEXEXTRACT($J$26:$J$31,""^[+-]?[0-9]*\.?[0-9]+""))= "&" VALUE(REGEXEXTRACT(M$26:M$31,""^[+-]?[0-9]*\.?[0-9]+"")))*1,0))) &""/""& SUM(ARRAYFORMULA(IFERROR( (VALUE(REGEXEXTRACT($J$26:$J$31,""^[+-]?[0-9]*\.?[0-9]+""))< VALUE(REGEXEXTRACT(M$26:M$31,""^[+-]?[0-9]*\.?[0-9]+"")))*1,0)))"),"4/2/0") -> 4/2/0 | N32: =IFERROR(__xludf.DUMMYFUNCTION("SUM(ARRAYFORMULA(IFERROR( (VALUE(REGEXEXTRACT($J$26:$J$31,""^[+-]?[0-9]*\.?[0-9]+""))> VALUE(REGEXEXTRACT(N$26:N$31,""^[+-]?[0-9]*\.?[0-9]+"")))*1,0))) &""/""& SUM(ARRAYFORMULA(IFERROR( (VALUE(REGEXEXTRACT($J$26:$J$31,""^[+-]?[0-9]*\.?[0-9]+""))= "&" VALUE(REGEXEXTRACT(N$26:N$31,""^[+-]?[0-9]*\.?[0-9]+"")))*1,0))) &""/""& SUM(ARRAYFORMULA(IFERROR( (VALUE(REGEXEXTRACT($J$26:$J$31,""^[+-]?[0-9]*\.?[0-9]+""))< VALUE(REGEXEXTRACT(N$26:N$31,""^[+-]?[0-9]*\.?[0-9]+"")))*1,0)))"),"2/2/2") -> 2/2/2 | O32: =IFERROR(__xludf.DUMMYFUNCTION("SUM(ARRAYFORMULA(IFERROR( (VALUE(REGEXEXTRACT($J$26:$J$31,""^[+-]?[0-9]*\.?[0-9]+""))> VALUE(REGEXEXTRACT(O$26:O$31,""^[+-]?[0-9]*\.?[0-9]+"")))*1,0))) &""/""& SUM(ARRAYFORMULA(IFERROR( (VALUE(REGEXEXTRACT($J$26:$J$31,""^[+-]?[0-9]*\.?[0-9]+""))= "&" VALUE(REGEXEXTRACT(O$26:O$31,""^[+-]?[0-9]*\.?[0-9]+"")))*1,0))) &""/""& SUM(ARRAYFORMULA(IFERROR( (VALUE(REGEXEXTRACT($J$26:$J$31,""^[+-]?[0-9]*\.?[0-9]+""))< VALUE(REGEXEXTRACT(O$26:O$31,""^[+-]?[0-9]*\.?[0-9]+"")))*1,0)))"),"2/2/2") -> 2/2/2 | P32: =IFERROR(__xludf.DUMMYFUNCTION("SUM(ARRAYFORMULA(IFERROR( (VALUE(REGEXEXTRACT($J$26:$J$31,""^[+-]?[0-9]*\.?[0-9]+""))> VALUE(REGEXEXTRACT(P$26:P$31,""^[+-]?[0-9]*\.?[0-9]+"")))*1,0))) &""/""& SUM(ARRAYFORMULA(IFERROR( (VALUE(REGEXEXTRACT($J$26:$J$31,""^[+-]?[0-9]*\.?[0-9]+""))= "&" VALUE(REGEXEXTRACT(P$26:P$31,""^[+-]?[0-9]*\.?[0-9]+"")))*1,0))) &""/""& SUM(ARRAYFORMULA(IFERROR( (VALUE(REGEXEXTRACT($J$26:$J$31,""^[+-]?[0-9]*\.?[0-9]+""))< VALUE(REGEXEXTRACT(P$26:P$31,""^[+-]?[0-9]*\.?[0-9]+"")))*1,0)))"),"4/2/0") -> 4/2/0
A33: Average (%) | B33: 74 | C33: 71.27 | D33: 58.35 | E33: 72.95 | F33: 73.5 | G33: 73.19 | H33: 60.59 | I33: =A33 -> Average (%) | J33: =IFERROR(__xludf.DUMMYFUNCTION("ROUND(AVERAGE(ARRAYFORMULA(IFERROR(VALUE(REGEXEXTRACT(J$26:J$31,""^[+-]?[0-9]*\.?[0-9]+"")),""""))),2)"),74.0) -> 74 | K33: =IFERROR(__xludf.DUMMYFUNCTION("ROUND(AVERAGE(ARRAYFORMULA(IFERROR(VALUE(REGEXEXTRACT(K$26:K$31,""^[+-]?[0-9]*\.?[0-9]+"")),""""))),2)"),71.27) -> 71.27 | L33: =IFERROR(__xludf.DUMMYFUNCTION("ROUND(AVERAGE(ARRAYFORMULA(IFERROR(VALUE(REGEXEXTRACT(L$26:L$31,""^[+-]?[0-9]*\.?[0-9]+"")),""""))),2)"),58.35) -> 58.35 | M33: =IFERROR(__xludf.DUMMYFUNCTION("ROUND(AVERAGE(ARRAYFORMULA(IFERROR(VALUE(REGEXEXTRACT(M$26:M$31,""^[+-]?[0-9]*\.?[0-9]+"")),""""))),2)"),72.95) -> 72.95 | N33: =IFERROR(__xludf.DUMMYFUNCTION("ROUND(AVERAGE(ARRAYFORMULA(IFERROR(VALUE(REGEXEXTRACT(N$26:N$31,""^[+-]?[0-9]*\.?[0-9]+"")),""""))),2)"),73.5) -> 73.5 | O33: =IFERROR(__xludf.DUMMYFUNCTION("ROUND(AVERAGE(ARRAYFORMULA(IFERROR(VALUE(REGEXEXTRACT(O$26:O$31,""^[+-]?[0-9]*\.?[0-9]+"")),""""))),2)"),73.19) -> 73.19 | P33: =IFERROR(__xludf.DUMMYFUNCTION("ROUND(AVERAGE(ARRAYFORMULA(IFERROR(VALUE(REGEXEXTRACT(P$26:P$31,""^[+-]?[0-9]*\.?[0-9]+"")),""""))),2)"),60.59) -> 60.59
A34: SOFTLAB | I34: SOFTLAB
A35: AR1→AR3 | B35: 0.7197 +/- 0.0130 | C35: 0.8023 +/- 0.0271 | D35: 0.7330 +/- 0.0229 | E35: 0.7836 +/- 0.0161 | F35: 0.7214 +/- 0.0163 | G35: 0.7185 +/- 0.0152 | H35: 0.8090 +/- 0.0214 | I35: =A35 -> AR1→AR3 | J35: =IFERROR(__xludf.DUMMYFUNCTION("TEXT(VALUE(REGEXEXTRACT(B35,""^[+-]?[0-9]*\.?[0-9]+""))*100,""0.00"")&"" +/- ""&TEXT(VALUE(REGEXEXTRACT(B35,""[0-9]*\.?[0-9]+$""))*100,""0.00"")"),"71.97 +/- 1.30") -> 71.97 +/- 1.30 | K35: =IFERROR(__xludf.DUMMYFUNCTION("TEXT(VALUE(REGEXEXTRACT(C35,""^[+-]?[0-9]*\.?[0-9]+""))*100,""0.00"")&"" +/- ""&TEXT(VALUE(REGEXEXTRACT(C35,""[0-9]*\.?[0-9]+$""))*100,""0.00"")"),"80.23 +/- 2.71") -> 80.23 +/- 2.71 | L35: =IFERROR(__xludf.DUMMYFUNCTION("TEXT(VALUE(REGEXEXTRACT(D35,""^[+-]?[0-9]*\.?[0-9]+""))*100,""0.00"")&"" +/- ""&TEXT(VALUE(REGEXEXTRACT(D35,""[0-9]*\.?[0-9]+$""))*100,""0.00"")"),"73.30 +/- 2.29") -> 73.30 +/- 2.29 | M35: =IFERROR(__xludf.DUMMYFUNCTION("TEXT(VALUE(REGEXEXTRACT(E35,""^[+-]?[0-9]*\.?[0-9]+""))*100,""0.00"")&"" +/- ""&TEXT(VALUE(REGEXEXTRACT(E35,""[0-9]*\.?[0-9]+$""))*100,""0.00"")"),"78.36 +/- 1.61") -> 78.36 +/- 1.61 | N35: =IFERROR(__xludf.DUMMYFUNCTION("TEXT(VALUE(REGEXEXTRACT(F35,""^[+-]?[0-9]*\.?[0-9]+""))*100,""0.00"")&"" +/- ""&TEXT(VALUE(REGEXEXTRACT(F35,""[0-9]*\.?[0-9]+$""))*100,""0.00"")"),"72.14 +/- 1.63") -> 72.14 +/- 1.63 | O35: =IFERROR(__xludf.DUMMYFUNCTION("TEXT(VALUE(REGEXEXTRACT(G35,""^[+-]?[0-9]*\.?[0-9]+""))*100,""0.00"")&"" +/- ""&TEXT(VALUE(REGEXEXTRACT(G35,""[0-9]*\.?[0-9]+$""))*100,""0.00"")"),"71.85 +/- 1.52") -> 71.85 +/- 1.52 | P35: =IFERROR(__xludf.DUMMYFUNCTION("TEXT(VALUE(REGEXEXTRACT(H35,""^[+-]?[0-9]*\.?[0-9]+""))*100,""0.00"")&"" +/- ""&TEXT(VALUE(REGEXEXTRACT(H35,""[0-9]*\.?[0-9]+$""))*100,""0.00"")"),"80.90 +/- 2.14") -> 80.90 +/- 2.14
A36: AR1→AR4 | B36: 0.7276 +/- 0.0158 | C36: 0.7524 +/- 0.0189 | D36: 0.6286 +/- 0.0238 | E36: 0.7541 +/- 0.0214 | F36: 0.7256 +/- 0.0133 | G36: 0.7231 +/- 0.0144 | H36: 0.7851 +/- 0.0178 | I36: =A36 -> AR1→AR4 | J36: =IFERROR(__xludf.DUMMYFUNCTION("TEXT(VALUE(REGEXEXTRACT(B36,""^[+-]?[0-9]*\.?[0-9]+""))*100,""0.00"")&"" +/- ""&TEXT(VALUE(REGEXEXTRACT(B36,""[0-9]*\.?[0-9]+$""))*100,""0.00"")"),"72.76 +/- 1.58") -> 72.76 +/- 1.58 | K36: =IFERROR(__xludf.DUMMYFUNCTION("TEXT(VALUE(REGEXEXTRACT(C36,""^[+-]?[0-9]*\.?[0-9]+""))*100,""0.00"")&"" +/- ""&TEXT(VALUE(REGEXEXTRACT(C36,""[0-9]*\.?[0-9]+$""))*100,""0.00"")"),"75.24 +/- 1.89") -> 75.24 +/- 1.89 | L36: =IFERROR(__xludf.DUMMYFUNCTION("TEXT(VALUE(REGEXEXTRACT(D36,""^[+-]?[0-9]*\.?[0-9]+""))*100,""0.00"")&"" +/- ""&TEXT(VALUE(REGEXEXTRACT(D36,""[0-9]*\.?[0-9]+$""))*100,""0.00"")"),"62.86 +/- 2.38") -> 62.86 +/- 2.38 | M36: =IFERROR(__xludf.DUMMYFUNCTION("TEXT(VALUE(REGEXEXTRACT(E36,""^[+-]?[0-9]*\.?[0-9]+""))*100,""0.00"")&"" +/- ""&TEXT(VALUE(REGEXEXTRACT(E36,""[0-9]*\.?[0-9]+$""))*100,""0.00"")"),"75.41 +/- 2.14") -> 75.41 +/- 2.14 | N36: =IFERROR(__xludf.DUMMYFUNCTION("TEXT(VALUE(REGEXEXTRACT(F36,""^[+-]?[0-9]*\.?[0-9]+""))*100,""0.00"")&"" +/- ""&TEXT(VALUE(REGEXEXTRACT(F36,""[0-9]*\.?[0-9]+$""))*100,""0.00"")"),"72.56 +/- 1.33") -> 72.56 +/- 1.33 | O36: =IFERROR(__xludf.DUMMYFUNCTION("TEXT(VALUE(REGEXEXTRACT(G36,""^[+-]?[0-9]*\.?[0-9]+""))*100,""0.00"")&"" +/- ""&TEXT(VALUE(REGEXEXTRACT(G36,""[0-9]*\.?[0-9]+$""))*100,""0.00"")"),"72.31 +/- 1.44") -> 72.31 +/- 1.44 | P36: =IFERROR(__xludf.DUMMYFUNCTION("TEXT(VALUE(REGEXEXTRACT(H36,""^[+-]?[0-9]*\.?[0-9]+""))*100,""0.00"")&"" +/- ""&TEXT(VALUE(REGEXEXTRACT(H36,""[0-9]*\.?[0-9]+$""))*100,""0.00"")"),"78.51 +/- 1.78") -> 78.51 +/- 1.78
